Workbook

Sheet Start Here
A1: NOVU · Habit Tracker
A2: One sheet per month, one tap per habit. Watch your consistency grow all year.
B4: متتبع العادات
B6: How to use
B7: 1. Setup | C7: Type the year and list up to 15 habits. They appear automatically on every month.
B8: 2. Months | C8: Open the current month and mark a habit as done with ✓ (pick it from the dropdown, or type x).
B9: 3. Progress | C9: Each habit shows days done and a completion rate; the bottom row shows how complete each day was.
B10: 4. Year | C10: A heat map of every habit across all 12 months.
B12: Legend
B13: Type here | C13: Tinted cells are inputs. Everything else calculates on its own — please don't type over it.
B14: Formula | C14: Dates, weekdays, totals, completion rates and the year heat map are formulas. October has a few sample marks — clear them when you start.
B16: Made by NOVU · Private by design. Your data stays in this file.
B17: Works in Microsoft Excel 2010+, Google Sheets and LibreOffice.

Sheet Setup
A1: Setup
A2: Year and habits · السنة والعادات
B4: Year | C4: 2026
B6: Habit | C6: Goal (days / month) | E6: Tips
B7: Pray Fajr on time | C7: 30 | E7: • Start small: 3–5 habits beat 15 you won't keep.
B8: Morning adhkar | C8: 30 | E8: • The goal is how many days a month you aim for — rest days are fine.
B9: Read 1 page of Quran | C9: 30 | E9: • Changing a habit name here updates every month.
B10: Drink 8 glasses of water | C10: 25
B11: Exercise 20 minutes | C11: 16
B12: Read 10 pages | C12: 20
B13: No social media before 10am | C13: 20
B14: Evening adhkar | C14: 30
B15: Learn something new | C15: 12
B16: Sleep before midnight | C16: 22

Sheet Year
A1: Year at a glance
A2: Completion rate per habit per month · السنة كاملة
B4: Habit | C4: Jan | D4: Feb | E4: Mar | F4: Apr | G4: May | H4: Jun | I4: Jul | J4: Aug | K4: Sep | L4: Oct | M4: Nov | N4: Dec | O4: Year
B5: =IF(Setup!B7="","",Setup!B7) | C5: =IF($B5="","",Jan!AJ6) | D5: =IF($B5="","",Feb!AJ6) | E5: =IF($B5="","",Mar!AJ6) | F5: =IF($B5="","",Apr!AJ6) | G5: =IF($B5="","",May!AJ6) | H5: =IF($B5="","",Jun!AJ6) | I5: =IF($B5="","",Jul!AJ6) | J5: =IF($B5="","",Aug!AJ6) | K5: =IF($B5="","",Sep!AJ6) | L5: =IF($B5="","",Oct!AJ6) | M5: =IF($B5="","",Nov!AJ6) | N5: =IF($B5="","",Dec!AJ6) | O5: =IF(B5="","",(N(Jan!AH6)+N(Feb!AH6)+N(Mar!AH6)+N(Apr!AH6)+N(May!AH6)+N(Jun!AH6)+N(Jul!AH6)+N(Aug!AH6)+N(Sep!AH6)+N(Oct!AH6)+N(Nov!AH6)+N(Dec!AH6))/(DATE(Setup!$C$4+1,1,1)-DATE(Setup!$C$4,1,1)))
B6: =IF(Setup!B8="","",Setup!B8) | C6: =IF($B6="","",Jan!AJ7) | D6: =IF($B6="","",Feb!AJ7) | E6: =IF($B6="","",Mar!AJ7) | F6: =IF($B6="","",Apr!AJ7) | G6: =IF($B6="","",May!AJ7) | H6: =IF($B6="","",Jun!AJ7) | I6: =IF($B6="","",Jul!AJ7) | J6: =IF($B6="","",Aug!AJ7) | K6: =IF($B6="","",Sep!AJ7) | L6: =IF($B6="","",Oct!AJ7) | M6: =IF($B6="","",Nov!AJ7) | N6: =IF($B6="","",Dec!AJ7) | O6: =IF(B6="","",(N(Jan!AH7)+N(Feb!AH7)+N(Mar!AH7)+N(Apr!AH7)+N(May!AH7)+N(Jun!AH7)+N(Jul!AH7)+N(Aug!AH7)+N(Sep!AH7)+N(Oct!AH7)+N(Nov!AH7)+N(Dec!AH7))/(DATE(Setup!$C$4+1,1,1)-DATE(Setup!$C$4,1,1)))
B7: =IF(Setup!B9="","",Setup!B9) | C7: =IF($B7="","",Jan!AJ8) | D7: =IF($B7="","",Feb!AJ8) | E7: =IF($B7="","",Mar!AJ8) | F7: =IF($B7="","",Apr!AJ8) | G7: =IF($B7="","",May!AJ8) | H7: =IF($B7="","",Jun!AJ8) | I7: =IF($B7="","",Jul!AJ8) | J7: =IF($B7="","",Aug!AJ8) | K7: =IF($B7="","",Sep!AJ8) | L7: =IF($B7="","",Oct!AJ8) | M7: =IF($B7="","",Nov!AJ8) | N7: =IF($B7="","",Dec!AJ8) | O7: =IF(B7="","",(N(Jan!AH8)+N(Feb!AH8)+N(Mar!AH8)+N(Apr!AH8)+N(May!AH8)+N(Jun!AH8)+N(Jul!AH8)+N(Aug!AH8)+N(Sep!AH8)+N(Oct!AH8)+N(Nov!AH8)+N(Dec!AH8))/(DATE(Setup!$C$4+1,1,1)-DATE(Setup!$C$4,1,1)))
B8: =IF(Setup!B10="","",Setup!B10) | C8: =IF($B8="","",Jan!AJ9) | D8: =IF($B8="","",Feb!AJ9) | E8: =IF($B8="","",Mar!AJ9) | F8: =IF($B8="","",Apr!AJ9) | G8: =IF($B8="","",May!AJ9) | H8: =IF($B8="","",Jun!AJ9) | I8: =IF($B8="","",Jul!AJ9) | J8: =IF($B8="","",Aug!AJ9) | K8: =IF($B8="","",Sep!AJ9) | L8: =IF($B8="","",Oct!AJ9) | M8: =IF($B8="","",Nov!AJ9) | N8: =IF($B8="","",Dec!AJ9) | O8: =IF(B8="","",(N(Jan!AH9)+N(Feb!AH9)+N(Mar!AH9)+N(Apr!AH9)+N(May!AH9)+N(Jun!AH9)+N(Jul!AH9)+N(Aug!AH9)+N(Sep!AH9)+N(Oct!AH9)+N(Nov!AH9)+N(Dec!AH9))/(DATE(Setup!$C$4+1,1,1)-DATE(Setup!$C$4,1,1)))
B9: =IF(Setup!B11="","",Setup!B11) | C9: =IF($B9="","",Jan!AJ10) | D9: =IF($B9="","",Feb!AJ10) | E9: =IF($B9="","",Mar!AJ10) | F9: =IF($B9="","",Apr!AJ10) | G9: =IF($B9="","",May!AJ10) | H9: =IF($B9="","",Jun!AJ10) | I9: =IF($B9="","",Jul!AJ10) | J9: =IF($B9="","",Aug!AJ10) | K9: =IF($B9="","",Sep!AJ10) | L9: =IF($B9="","",Oct!AJ10) | M9: =IF($B9="","",Nov!AJ10) | N9: =IF($B9="","",Dec!AJ10) | O9: =IF(B9="","",(N(Jan!AH10)+N(Feb!AH10)+N(Mar!AH10)+N(Apr!AH10)+N(May!AH10)+N(Jun!AH10)+N(Jul!AH10)+N(Aug!AH10)+N(Sep!AH10)+N(Oct!AH10)+N(Nov!AH10)+N(Dec!AH10))/(DATE(Setup!$C$4+1,1,1)-DATE(Setup!$C$4,1,1)))
B10: =IF(Setup!B12="","",Setup!B12) | C10: =IF($B10="","",Jan!AJ11) | D10: =IF($B10="","",Feb!AJ11) | E10: =IF($B10="","",Mar!AJ11) | F10: =IF($B10="","",Apr!AJ11) | G10: =IF($B10="","",May!AJ11) | H10: =IF($B10="","",Jun!AJ11) | I10: =IF($B10="","",Jul!AJ11) | J10: =IF($B10="","",Aug!AJ11) | K10: =IF($B10="","",Sep!AJ11) | L10: =IF($B10="","",Oct!AJ11) | M10: =IF($B10="","",Nov!AJ11) | N10: =IF($B10="","",Dec!AJ11) | O10: =IF(B10="","",(N(Jan!AH11)+N(Feb!AH11)+N(Mar!AH11)+N(Apr!AH11)+N(May!AH11)+N(Jun!AH11)+N(Jul!AH11)+N(Aug!AH11)+N(Sep!AH11)+N(Oct!AH11)+N(Nov!AH11)+N(Dec!AH11))/(DATE(Setup!$C$4+1,1,1)-DATE(Setup!$C$4,1,1)))
B11: =IF(Setup!B13="","",Setup!B13) | C11: =IF($B11="","",Jan!AJ12) | D11: =IF($B11="","",Feb!AJ12) | E11: =IF($B11="","",Mar!AJ12) | F11: =IF($B11="","",Apr!AJ12) | G11: =IF($B11="","",May!AJ12) | H11: =IF($B11="","",Jun!AJ12) | I11: =IF($B11="","",Jul!AJ12) | J11: =IF($B11="","",Aug!AJ12) | K11: =IF($B11="","",Sep!AJ12) | L11: =IF($B11="","",Oct!AJ12) | M11: =IF($B11="","",Nov!AJ12) | N11: =IF($B11="","",Dec!AJ12) | O11: =IF(B11="","",(N(Jan!AH12)+N(Feb!AH12)+N(Mar!AH12)+N(Apr!AH12)+N(May!AH12)+N(Jun!AH12)+N(Jul!AH12)+N(Aug!AH12)+N(Sep!AH12)+N(Oct!AH12)+N(Nov!AH12)+N(Dec!AH12))/(DATE(Setup!$C$4+1,1,1)-DATE(Setup!$C$4,1,1)))
B12: =IF(Setup!B14="","",Setup!B14) | C12: =IF($B12="","",Jan!AJ13) | D12: =IF($B12="","",Feb!AJ13) | E12: =IF($B12="","",Mar!AJ13) | F12: =IF($B12="","",Apr!AJ13) | G12: =IF($B12="","",May!AJ13) | H12: =IF($B12="","",Jun!AJ13) | I12: =IF($B12="","",Jul!AJ13) | J12: =IF($B12="","",Aug!AJ13) | K12: =IF($B12="","",Sep!AJ13) | L12: =IF($B12="","",Oct!AJ13) | M12: =IF($B12="","",Nov!AJ13) | N12: =IF($B12="","",Dec!AJ13) | O12: =IF(B12="","",(N(Jan!AH13)+N(Feb!AH13)+N(Mar!AH13)+N(Apr!AH13)+N(May!AH13)+N(Jun!AH13)+N(Jul!AH13)+N(Aug!AH13)+N(Sep!AH13)+N(Oct!AH13)+N(Nov!AH13)+N(Dec!AH13))/(DATE(Setup!$C$4+1,1,1)-DATE(Setup!$C$4,1,1)))
B13: =IF(Setup!B15="","",Setup!B15) | C13: =IF($B13="","",Jan!AJ14) | D13: =IF($B13="","",Feb!AJ14) | E13: =IF($B13="","",Mar!AJ14) | F13: =IF($B13="","",Apr!AJ14) | G13: =IF($B13="","",May!AJ14) | H13: =IF($B13="","",Jun!AJ14) | I13: =IF($B13="","",Jul!AJ14) | J13: =IF($B13="","",Aug!AJ14) | K13: =IF($B13="","",Sep!AJ14) | L13: =IF($B13="","",Oct!AJ14) | M13: =IF($B13="","",Nov!AJ14) | N13: =IF($B13="","",Dec!AJ14) | O13: =IF(B13="","",(N(Jan!AH14)+N(Feb!AH14)+N(Mar!AH14)+N(Apr!AH14)+N(May!AH14)+N(Jun!AH14)+N(Jul!AH14)+N(Aug!AH14)+N(Sep!AH14)+N(Oct!AH14)+N(Nov!AH14)+N(Dec!AH14))/(DATE(Setup!$C$4+1,1,1)-DATE(Setup!$C$4,1,1)))
B14: =IF(Setup!B16="","",Setup!B16) | C14: =IF($B14="","",Jan!AJ15) | D14: =IF($B14="","",Feb!AJ15) | E14: =IF($B14="","",Mar!AJ15) | F14: =IF($B14="","",Apr!AJ15) | G14: =IF($B14="","",May!AJ15) | H14: =IF($B14="","",Jun!AJ15) | I14: =IF($B14="","",Jul!AJ15) | J14: =IF($B14="","",Aug!AJ15) | K14: =IF($B14="","",Sep!AJ15) | L14: =IF($B14="","",Oct!AJ15) | M14: =IF($B14="","",Nov!AJ15) | N14: =IF($B14="","",Dec!AJ15) | O14: =IF(B14="","",(N(Jan!AH15)+N(Feb!AH15)+N(Mar!AH15)+N(Apr!AH15)+N(May!AH15)+N(Jun!AH15)+N(Jul!AH15)+N(Aug!AH15)+N(Sep!AH15)+N(Oct!AH15)+N(Nov!AH15)+N(Dec!AH15))/(DATE(Setup!$C$4+1,1,1)-DATE(Setup!$C$4,1,1)))
B15: =IF(Setup!B17="","",Setup!B17) | C15: =IF($B15="","",Jan!AJ16) | D15: =IF($B15="","",Feb!AJ16) | E15: =IF($B15="","",Mar!AJ16) | F15: =IF($B15="","",Apr!AJ16) | G15: =IF($B15="","",May!AJ16) | H15: =IF($B15="","",Jun!AJ16) | I15: =IF($B15="","",Jul!AJ16) | J15: =IF($B15="","",Aug!AJ16) | K15: =IF($B15="","",Sep!AJ16) | L15: =IF($B15="","",Oct!AJ16) | M15: =IF($B15="","",Nov!AJ16) | N15: =IF($B15="","",Dec!AJ16) | O15: =IF(B15="","",(N(Jan!AH16)+N(Feb!AH16)+N(Mar!AH16)+N(Apr!AH16)+N(May!AH16)+N(Jun!AH16)+N(Jul!AH16)+N(Aug!AH16)+N(Sep!AH16)+N(Oct!AH16)+N(Nov!AH16)+N(Dec!AH16))/(DATE(Setup!$C$4+1,1,1)-DATE(Setup!$C$4,1,1)))
B16: =IF(Setup!B18="","",Setup!B18) | C16: =IF($B16="","",Jan!AJ17) | D16: =IF($B16="","",Feb!AJ17) | E16: =IF($B16="","",Mar!AJ17) | F16: =IF($B16="","",Apr!AJ17) | G16: =IF($B16="","",May!AJ17) | H16: =IF($B16="","",Jun!AJ17) | I16: =IF($B16="","",Jul!AJ17) | J16: =IF($B16="","",Aug!AJ17) | K16: =IF($B16="","",Sep!AJ17) | L16: =IF($B16="","",Oct!AJ17) | M16: =IF($B16="","",Nov!AJ17) | N16: =IF($B16="","",Dec!AJ17) | O16: =IF(B16="","",(N(Jan!AH17)+N(Feb!AH17)+N(Mar!AH17)+N(Apr!AH17)+N(May!AH17)+N(Jun!AH17)+N(Jul!AH17)+N(Aug!AH17)+N(Sep!AH17)+N(Oct!AH17)+N(Nov!AH17)+N(Dec!AH17))/(DATE(Setup!$C$4+1,1,1)-DATE(Setup!$C$4,1,1)))
... B19: =IF(Setup!B21="","",Setup!B21) | C19: =IF($B19="","",Jan!AJ20) | D19: =IF($B19="","",Feb!AJ20) | E19: =IF($B19="","",Mar!AJ20) | F19: =IF($B19="","",Apr!AJ20) | G19: =IF($B19="","",May!AJ20) | H19: =IF($B19="","",Jun!AJ20) | I19: =IF($B19="","",Jul!AJ20) | J19: =IF($B19="","",Aug!AJ20) | K19: =IF($B19="","",Sep!AJ20) | L19: =IF($B19="","",Oct!AJ20) | M19: =IF($B19="","",Nov!AJ20) | N19: =IF($B19="","",Dec!AJ20) | O19: =IF(B19="","",(N(Jan!AH20)+N(Feb!AH20)+N(Mar!AH20)+N(Apr!AH20)+N(May!AH20)+N(Jun!AH20)+N(Jul!AH20)+N(Aug!AH20)+N(Sep!AH20)+N(Oct!AH20)+N(Nov!AH20)+N(Dec!AH20))/(DATE(Setup!$C$4+1,1,1)-DATE(Setup!$C$4,1,1)))
B20: Average | C20: =IFERROR(AVERAGE(C5:C19),"") | D20: =IFERROR(AVERAGE(D5:D19),"") | E20: =IFERROR(AVERAGE(E5:E19),"") | F20: =IFERROR(AVERAGE(F5:F19),"") | G20: =IFERROR(AVERAGE(G5:G19),"") | H20: =IFERROR(AVERAGE(H5:H19),"") | I20: =IFERROR(AVERAGE(I5:I19),"") | J20: =IFERROR(AVERAGE(J5:J19),"") | ... O20: =IFERROR(AVERAGE(O5:O19),"")

Sheet Jan
A1: =TEXT(DATE(Setup!$C$4,1,1),"mmmm yyyy")
A2: Mark ✓ when done · علّم ✓ عند الإنجاز
B4: Habit | C4: =IF(MONTH(DATE(Setup!$C$4,1,1))=1,DATE(Setup!$C$4,1,1),"") | D4: =IF(MONTH(DATE(Setup!$C$4,1,2))=1,DATE(Setup!$C$4,1,2),"") | E4: =IF(MONTH(DATE(Setup!$C$4,1,3))=1,DATE(Setup!$C$4,1,3),"") | F4: =IF(MONTH(DATE(Setup!$C$4,1,4))=1,DATE(Setup!$C$4,1,4),"") | G4: =IF(MONTH(DATE(Setup!$C$4,1,5))=1,DATE(Setup!$C$4,1,5),"") | H4: =IF(MONTH(DATE(Setup!$C$4,1,6))=1,DATE(Setup!$C$4,1,6),"") | I4: =IF(MONTH(DATE(Setup!$C$4,1,7))=1,DATE(Setup!$C$4,1,7),"") | J4: =IF(MONTH(DATE(Setup!$C$4,1,8))=1,DATE(Setup!$C$4,1,8),"") | K4: =IF(MONTH(DATE(Setup!$C$4,1,9))=1,DATE(Setup!$C$4,1,9),"") | L4: =IF(MONTH(DATE(Setup!$C$4,1,10))=1,DATE(Setup!$C$4,1,10),"") | M4: =IF(MONTH(DATE(Setup!$C$4,1,11))=1,DATE(Setup!$C$4,1,11),"") | N4: =IF(MONTH(DATE(Setup!$C$4,1,12))=1,DATE(Setup!$C$4,1,12),"") | O4: =IF(MONTH(DATE(Setup!$C$4,1,13))=1,DATE(Setup!$C$4,1,13),"") | P4: =IF(MONTH(DATE(Setup!$C$4,1,14))=1,DATE(Setup!$C$4,1,14),"") | Q4: =IF(MONTH(DATE(Setup!$C$4,1,15))=1,DATE(Setup!$C$4,1,15),"") | R4: =IF(MONTH(DATE(Setup!$C$4,1,16))=1,DATE(Setup!$C$4,1,16),"") | S4: =IF(MONTH(DATE(Setup!$C$4,1,17))=1,DATE(Setup!$C$4,1,17),"") | T4: =IF(MONTH(DATE(Setup!$C$4,1,18))=1,DATE(Setup!$C$4,1,18),"") | U4: =IF(MONTH(DATE(Setup!$C$4,1,19))=1,DATE(Setup!$C$4,1,19),"") | V4: =IF(MONTH(DATE(Setup!$C$4,1,20))=1,DATE(Setup!$C$4,1,20),"") | W4: =IF(MONTH(DATE(Setup!$C$4,1,21))=1,DATE(Setup!$C$4,1,21),"") | X4: =IF(MONTH(DATE(Setup!$C$4,1,22))=1,DATE(Setup!$C$4,1,22),"") | Y4: =IF(MONTH(DATE(Setup!$C$4,1,23))=1,DATE(Setup!$C$4,1,23),"") | Z4: =IF(MONTH(DATE(Setup!$C$4,1,24))=1,DATE(Setup!$C$4,1,24),"") | AA4: =IF(MONTH(DATE(Setup!$C$4,1,25))=1,DATE(Setup!$C$4,1,25),"") | AB4: =IF(MONTH(DATE(Setup!$C$4,1,26))=1,DATE(Setup!$C$4,1,26),"") | AC4: =IF(MONTH(DATE(Setup!$C$4,1,27))=1,DATE(Setup!$C$4,1,27),"") | AD4: =IF(MONTH(DATE(Setup!$C$4,1,28))=1,DATE(Setup!$C$4,1,28),"") | AE4: =IF(MONTH(DATE(Setup!$C$4,1,29))=1,DATE(Setup!$C$4,1,29),"") | AF4: =IF(MONTH(DATE(Setup!$C$4,1,30))=1,DATE(Setup!$C$4,1,30),"") | AG4: =IF(MONTH(DATE(Setup!$C$4,1,31))=1,DATE(Setup!$C$4,1,31),"") | AH4: Done | AI4: Goal | AJ4: Rate | AK4: vs goal
C5: =IF(C4="","",MID("SMTWTFS",WEEKDAY(C4),1)) | D5: =IF(D4="","",MID("SMTWTFS",WEEKDAY(D4),1)) | E5: =IF(E4="","",MID("SMTWTFS",WEEKDAY(E4),1)) | F5: =IF(F4="","",MID("SMTWTFS",WEEKDAY(F4),1)) | G5: =IF(G4="","",MID("SMTWTFS",WEEKDAY(G4),1)) | H5: =IF(H4="","",MID("SMTWTFS",WEEKDAY(H4),1)) | I5: =IF(I4="","",MID("SMTWTFS",WEEKDAY(I4),1)) | J5: =IF(J4="","",MID("SMTWTFS",WEEKDAY(J4),1)) | ... AG5: =IF(AG4="","",MID("SMTWTFS",WEEKDAY(AG4),1))
B6: =IF(Setup!B7="","",Setup!B7) | AH6: =IF(B6="","",COUNTIF(C6:AG6,"✓")+COUNTIF(C6:AG6,"x")) | AI6: =IF(OR(B6="",Setup!C7=""),"",MIN(Setup!C7,COUNT($C$4:$AG$4))) | AJ6: =IF(B6="","",AH6/COUNT($C$4:$AG$4)) | AK6: =IF(OR(B6="",N(AI6)=0),"",MIN(1,AH6/AI6))
B7: =IF(Setup!B8="","",Setup!B8) | AH7: =IF(B7="","",COUNTIF(C7:AG7,"✓")+COUNTIF(C7:AG7,"x")) | AI7: =IF(OR(B7="",Setup!C8=""),"",MIN(Setup!C8,COUNT($C$4:$AG$4))) | AJ7: =IF(B7="","",AH7/COUNT($C$4:$AG$4)) | AK7: =IF(OR(B7="",N(AI7)=0),"",MIN(1,AH7/AI7))
B8: =IF(Setup!B9="","",Setup!B9) | AH8: =IF(B8="","",COUNTIF(C8:AG8,"✓")+COUNTIF(C8:AG8,"x")) | AI8: =IF(OR(B8="",Setup!C9=""),"",MIN(Setup!C9,COUNT($C$4:$AG$4))) | AJ8: =IF(B8="","",AH8/COUNT($C$4:$AG$4)) | AK8: =IF(OR(B8="",N(AI8)=0),"",MIN(1,AH8/AI8))
B9: =IF(Setup!B10="","",Setup!B10) | AH9: =IF(B9="","",COUNTIF(C9:AG9,"✓")+COUNTIF(C9:AG9,"x")) | AI9: =IF(OR(B9="",Setup!C10=""),"",MIN(Setup!C10,COUNT($C$4:$AG$4))) | AJ9: =IF(B9="","",AH9/COUNT($C$4:$AG$4)) | AK9: =IF(OR(B9="",N(AI9)=0),"",MIN(1,AH9/AI9))
B10: =IF(Setup!B11="","",Setup!B11) | AH10: =IF(B10="","",COUNTIF(C10:AG10,"✓")+COUNTIF(C10:AG10,"x")) | AI10: =IF(OR(B10="",Setup!C11=""),"",MIN(Setup!C11,COUNT($C$4:$AG$4))) | AJ10: =IF(B10="","",AH10/COUNT($C$4:$AG$4)) | AK10: =IF(OR(B10="",N(AI10)=0),"",MIN(1,AH10/AI10))
B11: =IF(Setup!B12="","",Setup!B12) | AH11: =IF(B11="","",COUNTIF(C11:AG11,"✓")+COUNTIF(C11:AG11,"x")) | AI11: =IF(OR(B11="",Setup!C12=""),"",MIN(Setup!C12,COUNT($C$4:$AG$4))) | AJ11: =IF(B11="","",AH11/COUNT($C$4:$AG$4)) | AK11: =IF(OR(B11="",N(AI11)=0),"",MIN(1,AH11/AI11))
B12: =IF(Setup!B13="","",Setup!B13) | AH12: =IF(B12="","",COUNTIF(C12:AG12,"✓")+COUNTIF(C12:AG12,"x")) | AI12: =IF(OR(B12="",Setup!C13=""),"",MIN(Setup!C13,COUNT($C$4:$AG$4))) | AJ12: =IF(B12="","",AH12/COUNT($C$4:$AG$4)) | AK12: =IF(OR(B12="",N(AI12)=0),"",MIN(1,AH12/AI12))
B13: =IF(Setup!B14="","",Setup!B14) | AH13: =IF(B13="","",COUNTIF(C13:AG13,"✓")+COUNTIF(C13:AG13,"x")) | AI13: =IF(OR(B13="",Setup!C14=""),"",MIN(Setup!C14,COUNT($C$4:$AG$4))) | AJ13: =IF(B13="","",AH13/COUNT($C$4:$AG$4)) | AK13: =IF(OR(B13="",N(AI13)=0),"",MIN(1,AH13/AI13))
B14: =IF(Setup!B15="","",Setup!B15) | AH14: =IF(B14="","",COUNTIF(C14:AG14,"✓")+COUNTIF(C14:AG14,"x")) | AI14: =IF(OR(B14="",Setup!C15=""),"",MIN(Setup!C15,COUNT($C$4:$AG$4))) | AJ14: =IF(B14="","",AH14/COUNT($C$4:$AG$4)) | AK14: =IF(OR(B14="",N(AI14)=0),"",MIN(1,AH14/AI14))
B15: =IF(Setup!B16="","",Setup!B16) | AH15: =IF(B15="","",COUNTIF(C15:AG15,"✓")+COUNTIF(C15:AG15,"x")) | AI15: =IF(OR(B15="",Setup!C16=""),"",MIN(Setup!C16,COUNT($C$4:$AG$4))) | AJ15: =IF(B15="","",AH15/COUNT($C$4:$AG$4)) | AK15: =IF(OR(B15="",N(AI15)=0),"",MIN(1,AH15/AI15))
B16: =IF(Setup!B17="","",Setup!B17) | AH16: =IF(B16="","",COUNTIF(C16:AG16,"✓")+COUNTIF(C16:AG16,"x")) | AI16: =IF(OR(B16="",Setup!C17=""),"",MIN(Setup!C17,COUNT($C$4:$AG$4))) | AJ16: =IF(B16="","",AH16/COUNT($C$4:$AG$4)) | AK16: =IF(OR(B16="",N(AI16)=0),"",MIN(1,AH16/AI16))
B17: =IF(Setup!B18="","",Setup!B18) | AH17: =IF(B17="","",COUNTIF(C17:AG17,"✓")+COUNTIF(C17:AG17,"x")) | AI17: =IF(OR(B17="",Setup!C18=""),"",MIN(Setup!C18,COUNT($C$4:$AG$4))) | AJ17: =IF(B17="","",AH17/COUNT($C$4:$AG$4)) | AK17: =IF(OR(B17="",N(AI17)=0),"",MIN(1,AH17/AI17))
... B20: =IF(Setup!B21="","",Setup!B21) | AH20: =IF(B20="","",COUNTIF(C20:AG20,"✓")+COUNTIF(C20:AG20,"x")) | AI20: =IF(OR(B20="",Setup!C21=""),"",MIN(Setup!C21,COUNT($C$4:$AG$4))) | AJ20: =IF(B20="","",AH20/COUNT($C$4:$AG$4)) | AK20: =IF(OR(B20="",N(AI20)=0),"",MIN(1,AH20/AI20))
B21: Day complete | C21: =IF(OR(C4="",COUNTIF($B$6:$B$20,"?*")=0),"",(COUNTIF(C6:C20,"✓")+COUNTIF(C6:C20,"x"))/COUNTIF($B$6:$B$20,"?*")) | D21: =IF(OR(D4="",COUNTIF($B$6:$B$20,"?*")=0),"",(COUNTIF(D6:D20,"✓")+COUNTIF(D6:D20,"x"))/COUNTIF($B$6:$B$20,"?*")) | E21: =IF(OR(E4="",COUNTIF($B$6:$B$20,"?*")=0),"",(COUNTIF(E6:E20,"✓")+COUNTIF(E6:E20,"x"))/COUNTIF($B$6:$B$20,"?*")) | F21: =IF(OR(F4="",COUNTIF($B$6:$B$20,"?*")=0),"",(COUNTIF(F6:F20,"✓")+COUNTIF(F6:F20,"x"))/COUNTIF($B$6:$B$20,"?*")) | G21: =IF(OR(G4="",COUNTIF($B$6:$B$20,"?*")=0),"",(COUNTIF(G6:G20,"✓")+COUNTIF(G6:G20,"x"))/COUNTIF($B$6:$B$20,"?*")) | H21: =IF(OR(H4="",COUNTIF($B$6:$B$20,"?*")=0),"",(COUNTIF(H6:H20,"✓")+COUNTIF(H6:H20,"x"))/COUNTIF($B$6:$B$20,"?*")) | I21: =IF(OR(I4="",COUNTIF($B$6:$B$20,"?*")=0),"",(COUNTIF(I6:I20,"✓")+COUNTIF(I6:I20,"x"))/COUNTIF($B$6:$B$20,"?*")) | J21: =IF(OR(J4="",COUNTIF($B$6:$B$20,"?*")=0),"",(COUNTIF(J6:J20,"✓")+COUNTIF(J6:J20,"x"))/COUNTIF($B$6:$B$20,"?*")) | ... AG21: =IF(OR(AG4="",COUNTIF($B$6:$B$20,"?*")=0),"",(COUNTIF(AG6:AG20,"✓")+COUNTIF(AG6:AG20,"x"))/COUNTIF($B$6:$B$20,"?*")) | AJ21: =IFERROR(AVERAGE(AJ6:AJ20),"")

Sheet Feb
A1: =TEXT(DATE(Setup!$C$4,2,1),"mmmm yyyy")
A2: Mark ✓ when done · علّم ✓ عند الإنجاز
B4: Habit | C4: =IF(MONTH(DATE(Setup!$C$4,2,1))=2,DATE(Setup!$C$4,2,1),"") | D4: =IF(MONTH(DATE(Setup!$C$4,2,2))=2,DATE(Setup!$C$4,2,2),"") | E4: =IF(MONTH(DATE(Setup!$C$4,2,3))=2,DATE(Setup!$C$4,2,3),"") | F4: =IF(MONTH(DATE(Setup!$C$4,2,4))=2,DATE(Setup!$C$4,2,4),"") | G4: =IF(MONTH(DATE(Setup!$C$4,2,5))=2,DATE(Setup!$C$4,2,5),"") | H4: =IF(MONTH(DATE(Setup!$C$4,2,6))=2,DATE(Setup!$C$4,2,6),"") | I4: =IF(MONTH(DATE(Setup!$C$4,2,7))=2,DATE(Setup!$C$4,2,7),"") | J4: =IF(MONTH(DATE(Setup!$C$4,2,8))=2,DATE(Setup!$C$4,2,8),"") | K4: =IF(MONTH(DATE(Setup!$C$4,2,9))=2,DATE(Setup!$C$4,2,9),"") | L4: =IF(MONTH(DATE(Setup!$C$4,2,10))=2,DATE(Setup!$C$4,2,10),"") | M4: =IF(MONTH(DATE(Setup!$C$4,2,11))=2,DATE(Setup!$C$4,2,11),"") | N4: =IF(MONTH(DATE(Setup!$C$4,2,12))=2,DATE(Setup!$C$4,2,12),"") | O4: =IF(MONTH(DATE(Setup!$C$4,2,13))=2,DATE(Setup!$C$4,2,13),"") | P4: =IF(MONTH(DATE(Setup!$C$4,2,14))=2,DATE(Setup!$C$4,2,14),"") | Q4: =IF(MONTH(DATE(Setup!$C$4,2,15))=2,DATE(Setup!$C$4,2,15),"") | R4: =IF(MONTH(DATE(Setup!$C$4,2,16))=2,DATE(Setup!$C$4,2,16),"") | S4: =IF(MONTH(DATE(Setup!$C$4,2,17))=2,DATE(Setup!$C$4,2,17),"") | T4: =IF(MONTH(DATE(Setup!$C$4,2,18))=2,DATE(Setup!$C$4,2,18),"") | U4: =IF(MONTH(DATE(Setup!$C$4,2,19))=2,DATE(Setup!$C$4,2,19),"") | V4: =IF(MONTH(DATE(Setup!$C$4,2,20))=2,DATE(Setup!$C$4,2,20),"") | W4: =IF(MONTH(DATE(Setup!$C$4,2,21))=2,DATE(Setup!$C$4,2,21),"") | X4: =IF(MONTH(DATE(Setup!$C$4,2,22))=2,DATE(Setup!$C$4,2,22),"") | Y4: =IF(MONTH(DATE(Setup!$C$4,2,23))=2,DATE(Setup!$C$4,2,23),"") | Z4: =IF(MONTH(DATE(Setup!$C$4,2,24))=2,DATE(Setup!$C$4,2,24),"") | AA4: =IF(MONTH(DATE(Setup!$C$4,2,25))=2,DATE(Setup!$C$4,2,25),"") | AB4: =IF(MONTH(DATE(Setup!$C$4,2,26))=2,DATE(Setup!$C$4,2,26),"") | AC4: =IF(MONTH(DATE(Setup!$C$4,2,27))=2,DATE(Setup!$C$4,2,27),"") | AD4: =IF(MONTH(DATE(Setup!$C$4,2,28))=2,DATE(Setup!$C$4,2,28),"") | AE4: =IF(MONTH(DATE(Setup!$C$4,2,29))=2,DATE(Setup!$C$4,2,29),"") | AF4: =IF(MONTH(DATE(Setup!$C$4,2,30))=2,DATE(Setup!$C$4,2,30),"") | AG4: =IF(MONTH(DATE(Setup!$C$4,2,31))=2,DATE(Setup!$C$4,2,31),"") | AH4: Done | AI4: Goal | AJ4: Rate | AK4: vs goal
C5: =IF(C4="","",MID("SMTWTFS",WEEKDAY(C4),1)) | D5: =IF(D4="","",MID("SMTWTFS",WEEKDAY(D4),1)) | E5: =IF(E4="","",MID("SMTWTFS",WEEKDAY(E4),1)) | F5: =IF(F4="","",MID("SMTWTFS",WEEKDAY(F4),1)) | G5: =IF(G4="","",MID("SMTWTFS",WEEKDAY(G4),1)) | H5: =IF(H4="","",MID("SMTWTFS",WEEKDAY(H4),1)) | I5: =IF(I4="","",MID("SMTWTFS",WEEKDAY(I4),1)) | J5: =IF(J4="","",MID("SMTWTFS",WEEKDAY(J4),1)) | ... AG5: =IF(AG4="","",MID("SMTWTFS",WEEKDAY(AG4),1))
B6: =IF(Setup!B7="","",Setup!B7) | AH6: =IF(B6="","",COUNTIF(C6:AG6,"✓")+COUNTIF(C6:AG6,"x")) | AI6: =IF(OR(B6="",Setup!C7=""),"",MIN(Setup!C7,COUNT($C$4:$AG$4))) | AJ6: =IF(B6="","",AH6/COUNT($C$4:$AG$4)) | AK6: =IF(OR(B6="",N(AI6)=0),"",MIN(1,AH6/AI6))
B7: =IF(Setup!B8="","",Setup!B8) | AH7: =IF(B7="","",COUNTIF(C7:AG7,"✓")+COUNTIF(C7:AG7,"x")) | AI7: =IF(OR(B7="",Setup!C8=""),"",MIN(Setup!C8,COUNT($C$4:$AG$4))) | AJ7: =IF(B7="","",AH7/COUNT($C$4:$AG$4)) | AK7: =IF(OR(B7="",N(AI7)=0),"",MIN(1,AH7/AI7))
B8: =IF(Setup!B9="","",Setup!B9) | AH8: =IF(B8="","",COUNTIF(C8:AG8,"✓")+COUNTIF(C8:AG8,"x")) | AI8: =IF(OR(B8="",Setup!C9=""),"",MIN(Setup!C9,COUNT($C$4:$AG$4))) | AJ8: =IF(B8="","",AH8/COUNT($C$4:$AG$4)) | AK8: =IF(OR(B8="",N(AI8)=0),"",MIN(1,AH8/AI8))
B9: =IF(Setup!B10="","",Setup!B10) | AH9: =IF(B9="","",COUNTIF(C9:AG9,"✓")+COUNTIF(C9:AG9,"x")) | AI9: =IF(OR(B9="",Setup!C10=""),"",MIN(Setup!C10,COUNT($C$4:$AG$4))) | AJ9: =IF(B9="","",AH9/COUNT($C$4:$AG$4)) | AK9: =IF(OR(B9="",N(AI9)=0),"",MIN(1,AH9/AI9))
B10: =IF(Setup!B11="","",Setup!B11) | AH10: =IF(B10="","",COUNTIF(C10:AG10,"✓")+COUNTIF(C10:AG10,"x")) | AI10: =IF(OR(B10="",Setup!C11=""),"",MIN(Setup!C11,COUNT($C$4:$AG$4))) | AJ10: =IF(B10="","",AH10/COUNT($C$4:$AG$4)) | AK10: =IF(OR(B10="",N(AI10)=0),"",MIN(1,AH10/AI10))
B11: =IF(Setup!B12="","",Setup!B12) | AH11: =IF(B11="","",COUNTIF(C11:AG11,"✓")+COUNTIF(C11:AG11,"x")) | AI11: =IF(OR(B11="",Setup!C12=""),"",MIN(Setup!C12,COUNT($C$4:$AG$4))) | AJ11: =IF(B11="","",AH11/COUNT($C$4:$AG$4)) | AK11: =IF(OR(B11="",N(AI11)=0),"",MIN(1,AH11/AI11))
B12: =IF(Setup!B13="","",Setup!B13) | AH12: =IF(B12="","",COUNTIF(C12:AG12,"✓")+COUNTIF(C12:AG12,"x")) | AI12: =IF(OR(B12="",Setup!C13=""),"",MIN(Setup!C13,COUNT($C$4:$AG$4))) | AJ12: =IF(B12="","",AH12/COUNT($C$4:$AG$4)) | AK12: =IF(OR(B12="",N(AI12)=0),"",MIN(1,AH12/AI12))
B13: =IF(Setup!B14="","",Setup!B14) | AH13: =IF(B13="","",COUNTIF(C13:AG13,"✓")+COUNTIF(C13:AG13,"x")) | AI13: =IF(OR(B13="",Setup!C14=""),"",MIN(Setup!C14,COUNT($C$4:$AG$4))) | AJ13: =IF(B13="","",AH13/COUNT($C$4:$AG$4)) | AK13: =IF(OR(B13="",N(AI13)=0),"",MIN(1,AH13/AI13))
B14: =IF(Setup!B15="","",Setup!B15) | AH14: =IF(B14="","",COUNTIF(C14:AG14,"✓")+COUNTIF(C14:AG14,"x")) | AI14: =IF(OR(B14="",Setup!C15=""),"",MIN(Setup!C15,COUNT($C$4:$AG$4))) | AJ14: =IF(B14="","",AH14/COUNT($C$4:$AG$4)) | AK14: =IF(OR(B14="",N(AI14)=0),"",MIN(1,AH14/AI14))
B15: =IF(Setup!B16="","",Setup!B16) | AH15: =IF(B15="","",COUNTIF(C15:AG15,"✓")+COUNTIF(C15:AG15,"x")) | AI15: =IF(OR(B15="",Setup!C16=""),"",MIN(Setup!C16,COUNT($C$4:$AG$4))) | AJ15: =IF(B15="","",AH15/COUNT($C$4:$AG$4)) | AK15: =IF(OR(B15="",N(AI15)=0),"",MIN(1,AH15/AI15))
B16: =IF(Setup!B17="","",Setup!B17) | AH16: =IF(B16="","",COUNTIF(C16:AG16,"✓")+COUNTIF(C16:AG16,"x")) | AI16: =IF(OR(B16="",Setup!C17=""),"",MIN(Setup!C17,COUNT($C$4:$AG$4))) | AJ16: =IF(B16="","",AH16/COUNT($C$4:$AG$4)) | AK16: =IF(OR(B16="",N(AI16)=0),"",MIN(1,AH16/AI16))
B17: =IF(Setup!B18="","",Setup!B18) | AH17: =IF(B17="","",COUNTIF(C17:AG17,"✓")+COUNTIF(C17:AG17,"x")) | AI17: =IF(OR(B17="",Setup!C18=""),"",MIN(Setup!C18,COUNT($C$4:$AG$4))) | AJ17: =IF(B17="","",AH17/COUNT($C$4:$AG$4)) | AK17: =IF(OR(B17="",N(AI17)=0),"",MIN(1,AH17/AI17))
... B20: =IF(Setup!B21="","",Setup!B21) | AH20: =IF(B20="","",COUNTIF(C20:AG20,"✓")+COUNTIF(C20:AG20,"x")) | AI20: =IF(OR(B20="",Setup!C21=""),"",MIN(Setup!C21,COUNT($C$4:$AG$4))) | AJ20: =IF(B20="","",AH20/COUNT($C$4:$AG$4)) | AK20: =IF(OR(B20="",N(AI20)=0),"",MIN(1,AH20/AI20))
B21: Day complete | C21: =IF(OR(C4="",COUNTIF($B$6:$B$20,"?*")=0),"",(COUNTIF(C6:C20,"✓")+COUNTIF(C6:C20,"x"))/COUNTIF($B$6:$B$20,"?*")) | D21: =IF(OR(D4="",COUNTIF($B$6:$B$20,"?*")=0),"",(COUNTIF(D6:D20,"✓")+COUNTIF(D6:D20,"x"))/COUNTIF($B$6:$B$20,"?*")) | E21: =IF(OR(E4="",COUNTIF($B$6:$B$20,"?*")=0),"",(COUNTIF(E6:E20,"✓")+COUNTIF(E6:E20,"x"))/COUNTIF($B$6:$B$20,"?*")) | F21: =IF(OR(F4="",COUNTIF($B$6:$B$20,"?*")=0),"",(COUNTIF(F6:F20,"✓")+COUNTIF(F6:F20,"x"))/COUNTIF($B$6:$B$20,"?*")) | G21: =IF(OR(G4="",COUNTIF($B$6:$B$20,"?*")=0),"",(COUNTIF(G6:G20,"✓")+COUNTIF(G6:G20,"x"))/COUNTIF($B$6:$B$20,"?*")) | H21: =IF(OR(H4="",COUNTIF($B$6:$B$20,"?*")=0),"",(COUNTIF(H6:H20,"✓")+COUNTIF(H6:H20,"x"))/COUNTIF($B$6:$B$20,"?*")) | I21: =IF(OR(I4="",COUNTIF($B$6:$B$20,"?*")=0),"",(COUNTIF(I6:I20,"✓")+COUNTIF(I6:I20,"x"))/COUNTIF($B$6:$B$20,"?*")) | J21: =IF(OR(J4="",COUNTIF($B$6:$B$20,"?*")=0),"",(COUNTIF(J6:J20,"✓")+COUNTIF(J6:J20,"x"))/COUNTIF($B$6:$B$20,"?*")) | ... AG21: =IF(OR(AG4="",COUNTIF($B$6:$B$20,"?*")=0),"",(COUNTIF(AG6:AG20,"✓")+COUNTIF(AG6:AG20,"x"))/COUNTIF($B$6:$B$20,"?*")) | AJ21: =IFERROR(AVERAGE(AJ6:AJ20),"")

Sheet Mar
A1: =TEXT(DATE(Setup!$C$4,3,1),"mmmm yyyy")
A2: Mark ✓ when done · علّم ✓ عند الإنجاز
B4: Habit | C4: =IF(MONTH(DATE(Setup!$C$4,3,1))=3,DATE(Setup!$C$4,3,1),"") | D4: =IF(MONTH(DATE(Setup!$C$4,3,2))=3,DATE(Setup!$C$4,3,2),"") | E4: =IF(MONTH(DATE(Setup!$C$4,3,3))=3,DATE(Setup!$C$4,3,3),"") | F4: =IF(MONTH(DATE(Setup!$C$4,3,4))=3,DATE(Setup!$C$4,3,4),"") | G4: =IF(MONTH(DATE(Setup!$C$4,3,5))=3,DATE(Setup!$C$4,3,5),"") | H4: =IF(MONTH(DATE(Setup!$C$4,3,6))=3,DATE(Setup!$C$4,3,6),"") | I4: =IF(MONTH(DATE(Setup!$C$4,3,7))=3,DATE(Setup!$C$4,3,7),"") | J4: =IF(MONTH(DATE(Setup!$C$4,3,8))=3,DATE(Setup!$C$4,3,8),"") | K4: =IF(MONTH(DATE(Setup!$C$4,3,9))=3,DATE(Setup!$C$4,3,9),"") | L4: =IF(MONTH(DATE(Setup!$C$4,3,10))=3,DATE(Setup!$C$4,3,10),"") | M4: =IF(MONTH(DATE(Setup!$C$4,3,11))=3,DATE(Setup!$C$4,3,11),"") | N4: =IF(MONTH(DATE(Setup!$C$4,3,12))=3,DATE(Setup!$C$4,3,12),"") | O4: =IF(MONTH(DATE(Setup!$C$4,3,13))=3,DATE(Setup!$C$4,3,13),"") | P4: =IF(MONTH(DATE(Setup!$C$4,3,14))=3,DATE(Setup!$C$4,3,14),"") | Q4: =IF(MONTH(DATE(Setup!$C$4,3,15))=3,DATE(Setup!$C$4,3,15),"") | R4: =IF(MONTH(DATE(Setup!$C$4,3,16))=3,DATE(Setup!$C$4,3,16),"") | S4: =IF(MONTH(DATE(Setup!$C$4,3,17))=3,DATE(Setup!$C$4,3,17),"") | T4: =IF(MONTH(DATE(Setup!$C$4,3,18))=3,DATE(Setup!$C$4,3,18),"") | U4: =IF(MONTH(DATE(Setup!$C$4,3,19))=3,DATE(Setup!$C$4,3,19),"") | V4: =IF(MONTH(DATE(Setup!$C$4,3,20))=3,DATE(Setup!$C$4,3,20),"") | W4: =IF(MONTH(DATE(Setup!$C$4,3,21))=3,DATE(Setup!$C$4,3,21),"") | X4: =IF(MONTH(DATE(Setup!$C$4,3,22))=3,DATE(Setup!$C$4,3,22),"") | Y4: =IF(MONTH(DATE(Setup!$C$4,3,23))=3,DATE(Setup!$C$4,3,23),"") | Z4: =IF(MONTH(DATE(Setup!$C$4,3,24))=3,DATE(Setup!$C$4,3,24),"") | AA4: =IF(MONTH(DATE(Setup!$C$4,3,25))=3,DATE(Setup!$C$4,3,25),"") | AB4: =IF(MONTH(DATE(Setup!$C$4,3,26))=3,DATE(Setup!$C$4,3,26),"") | AC4: =IF(MONTH(DATE(Setup!$C$4,3,27))=3,DATE(Setup!$C$4,3,27),"") | AD4: =IF(MONTH(DATE(Setup!$C$4,3,28))=3,DATE(Setup!$C$4,3,28),"") | AE4: =IF(MONTH(DATE(Setup!$C$4,3,29))=3,DATE(Setup!$C$4,3,29),"") | AF4: =IF(MONTH(DATE(Setup!$C$4,3,30))=3,DATE(Setup!$C$4,3,30),"") | AG4: =IF(MONTH(DATE(Setup!$C$4,3,31))=3,DATE(Setup!$C$4,3,31),"") | AH4: Done | AI4: Goal | AJ4: Rate | AK4: vs goal
C5: =IF(C4="","",MID("SMTWTFS",WEEKDAY(C4),1)) | D5: =IF(D4="","",MID("SMTWTFS",WEEKDAY(D4),1)) | E5: =IF(E4="","",MID("SMTWTFS",WEEKDAY(E4),1)) | F5: =IF(F4="","",MID("SMTWTFS",WEEKDAY(F4),1)) | G5: =IF(G4="","",MID("SMTWTFS",WEEKDAY(G4),1)) | H5: =IF(H4="","",MID("SMTWTFS",WEEKDAY(H4),1)) | I5: =IF(I4="","",MID("SMTWTFS",WEEKDAY(I4),1)) | J5: =IF(J4="","",MID("SMTWTFS",WEEKDAY(J4),1)) | ... AG5: =IF(AG4="","",MID("SMTWTFS",WEEKDAY(AG4),1))
B6: =IF(Setup!B7="","",Setup!B7) | AH6: =IF(B6="","",COUNTIF(C6:AG6,"✓")+COUNTIF(C6:AG6,"x")) | AI6: =IF(OR(B6="",Setup!C7=""),"",MIN(Setup!C7,COUNT($C$4:$AG$4))) | AJ6: =IF(B6="","",AH6/COUNT($C$4:$AG$4)) | AK6: =IF(OR(B6="",N(AI6)=0),"",MIN(1,AH6/AI6))
B7: =IF(Setup!B8="","",Setup!B8) | AH7: =IF(B7="","",COUNTIF(C7:AG7,"✓")+COUNTIF(C7:AG7,"x")) | AI7: =IF(OR(B7="",Setup!C8=""),"",MIN(Setup!C8,COUNT($C$4:$AG$4))) | AJ7: =IF(B7="","",AH7/COUNT($C$4:$AG$4)) | AK7: =IF(OR(B7="",N(AI7)=0),"",MIN(1,AH7/AI7))
B8: =IF(Setup!B9="","",Setup!B9) | AH8: =IF(B8="","",COUNTIF(C8:AG8,"✓")+COUNTIF(C8:AG8,"x")) | AI8: =IF(OR(B8="",Setup!C9=""),"",MIN(Setup!C9,COUNT($C$4:$AG$4))) | AJ8: =IF(B8="","",AH8/COUNT($C$4:$AG$4)) | AK8: =IF(OR(B8="",N(AI8)=0),"",MIN(1,AH8/AI8))
B9: =IF(Setup!B10="","",Setup!B10) | AH9: =IF(B9="","",COUNTIF(C9:AG9,"✓")+COUNTIF(C9:AG9,"x")) | AI9: =IF(OR(B9="",Setup!C10=""),"",MIN(Setup!C10,COUNT($C$4:$AG$4))) | AJ9: =IF(B9="","",AH9/COUNT($C$4:$AG$4)) | AK9: =IF(OR(B9="",N(AI9)=0),"",MIN(1,AH9/AI9))
B10: =IF(Setup!B11="","",Setup!B11) | AH10: =IF(B10="","",COUNTIF(C10:AG10,"✓")+COUNTIF(C10:AG10,"x")) | AI10: =IF(OR(B10="",Setup!C11=""),"",MIN(Setup!C11,COUNT($C$4:$AG$4))) | AJ10: =IF(B10="","",AH10/COUNT($C$4:$AG$4)) | AK10: =IF(OR(B10="",N(AI10)=0),"",MIN(1,AH10/AI10))
B11: =IF(Setup!B12="","",Setup!B12) | AH11: =IF(B11="","",COUNTIF(C11:AG11,"✓")+COUNTIF(C11:AG11,"x")) | AI11: =IF(OR(B11="",Setup!C12=""),"",MIN(Setup!C12,COUNT($C$4:$AG$4))) | AJ11: =IF(B11="","",AH11/COUNT($C$4:$AG$4)) | AK11: =IF(OR(B11="",N(AI11)=0),"",MIN(1,AH11/AI11))
B12: =IF(Setup!B13="","",Setup!B13) | AH12: =IF(B12="","",COUNTIF(C12:AG12,"✓")+COUNTIF(C12:AG12,"x")) | AI12: =IF(OR(B12="",Setup!C13=""),"",MIN(Setup!C13,COUNT($C$4:$AG$4))) | AJ12: =IF(B12="","",AH12/COUNT($C$4:$AG$4)) | AK12: =IF(OR(B12="",N(AI12)=0),"",MIN(1,AH12/AI12))
B13: =IF(Setup!B14="","",Setup!B14) | AH13: =IF(B13="","",COUNTIF(C13:AG13,"✓")+COUNTIF(C13:AG13,"x")) | AI13: =IF(OR(B13="",Setup!C14=""),"",MIN(Setup!C14,COUNT($C$4:$AG$4))) | AJ13: =IF(B13="","",AH13/COUNT($C$4:$AG$4)) | AK13: =IF(OR(B13="",N(AI13)=0),"",MIN(1,AH13/AI13))
B14: =IF(Setup!B15="","",Setup!B15) | AH14: =IF(B14="","",COUNTIF(C14:AG14,"✓")+COUNTIF(C14:AG14,"x")) | AI14: =IF(OR(B14="",Setup!C15=""),"",MIN(Setup!C15,COUNT($C$4:$AG$4))) | AJ14: =IF(B14="","",AH14/COUNT($C$4:$AG$4)) | AK14: =IF(OR(B14="",N(AI14)=0),"",MIN(1,AH14/AI14))
B15: =IF(Setup!B16="","",Setup!B16) | AH15: =IF(B15="","",COUNTIF(C15:AG15,"✓")+COUNTIF(C15:AG15,"x")) | AI15: =IF(OR(B15="",Setup!C16=""),"",MIN(Setup!C16,COUNT($C$4:$AG$4))) | AJ15: =IF(B15="","",AH15/COUNT($C$4:$AG$4)) | AK15: =IF(OR(B15="",N(AI15)=0),"",MIN(1,AH15/AI15))
B16: =IF(Setup!B17="","",Setup!B17) | AH16: =IF(B16="","",COUNTIF(C16:AG16,"✓")+COUNTIF(C16:AG16,"x")) | AI16: =IF(OR(B16="",Setup!C17=""),"",MIN(Setup!C17,COUNT($C$4:$AG$4))) | AJ16: =IF(B16="","",AH16/COUNT($C$4:$AG$4)) | AK16: =IF(OR(B16="",N(AI16)=0),"",MIN(1,AH16/AI16))
B17: =IF(Setup!B18="","",Setup!B18) | AH17: =IF(B17="","",COUNTIF(C17:AG17,"✓")+COUNTIF(C17:AG17,"x")) | AI17: =IF(OR(B17="",Setup!C18=""),"",MIN(Setup!C18,COUNT($C$4:$AG$4))) | AJ17: =IF(B17="","",AH17/COUNT($C$4:$AG$4)) | AK17: =IF(OR(B17="",N(AI17)=0),"",MIN(1,AH17/AI17))
... B20: =IF(Setup!B21="","",Setup!B21) | AH20: =IF(B20="","",COUNTIF(C20:AG20,"✓")+COUNTIF(C20:AG20,"x")) | AI20: =IF(OR(B20="",Setup!C21=""),"",MIN(Setup!C21,COUNT($C$4:$AG$4))) | AJ20: =IF(B20="","",AH20/COUNT($C$4:$AG$4)) | AK20: =IF(OR(B20="",N(AI20)=0),"",MIN(1,AH20/AI20))
B21: Day complete | C21: =IF(OR(C4="",COUNTIF($B$6:$B$20,"?*")=0),"",(COUNTIF(C6:C20,"✓")+COUNTIF(C6:C20,"x"))/COUNTIF($B$6:$B$20,"?*")) | D21: =IF(OR(D4="",COUNTIF($B$6:$B$20,"?*")=0),"",(COUNTIF(D6:D20,"✓")+COUNTIF(D6:D20,"x"))/COUNTIF($B$6:$B$20,"?*")) | E21: =IF(OR(E4="",COUNTIF($B$6:$B$20,"?*")=0),"",(COUNTIF(E6:E20,"✓")+COUNTIF(E6:E20,"x"))/COUNTIF($B$6:$B$20,"?*")) | F21: =IF(OR(F4="",COUNTIF($B$6:$B$20,"?*")=0),"",(COUNTIF(F6:F20,"✓")+COUNTIF(F6:F20,"x"))/COUNTIF($B$6:$B$20,"?*")) | G21: =IF(OR(G4="",COUNTIF($B$6:$B$20,"?*")=0),"",(COUNTIF(G6:G20,"✓")+COUNTIF(G6:G20,"x"))/COUNTIF($B$6:$B$20,"?*")) | H21: =IF(OR(H4="",COUNTIF($B$6:$B$20,"?*")=0),"",(COUNTIF(H6:H20,"✓")+COUNTIF(H6:H20,"x"))/COUNTIF($B$6:$B$20,"?*")) | I21: =IF(OR(I4="",COUNTIF($B$6:$B$20,"?*")=0),"",(COUNTIF(I6:I20,"✓")+COUNTIF(I6:I20,"x"))/COUNTIF($B$6:$B$20,"?*")) | J21: =IF(OR(J4="",COUNTIF($B$6:$B$20,"?*")=0),"",(COUNTIF(J6:J20,"✓")+COUNTIF(J6:J20,"x"))/COUNTIF($B$6:$B$20,"?*")) | ... AG21: =IF(OR(AG4="",COUNTIF($B$6:$B$20,"?*")=0),"",(COUNTIF(AG6:AG20,"✓")+COUNTIF(AG6:AG20,"x"))/COUNTIF($B$6:$B$20,"?*")) | AJ21: =IFERROR(AVERAGE(AJ6:AJ20),"")

Sheet Apr
A1: =TEXT(DATE(Setup!$C$4,4,1),"mmmm yyyy")
A2: Mark ✓ when done · علّم ✓ عند الإنجاز
B4: Habit | C4: =IF(MONTH(DATE(Setup!$C$4,4,1))=4,DATE(Setup!$C$4,4,1),"") | D4: =IF(MONTH(DATE(Setup!$C$4,4,2))=4,DATE(Setup!$C$4,4,2),"") | E4: =IF(MONTH(DATE(Setup!$C$4,4,3))=4,DATE(Setup!$C$4,4,3),"") | F4: =IF(MONTH(DATE(Setup!$C$4,4,4))=4,DATE(Setup!$C$4,4,4),"") | G4: =IF(MONTH(DATE(Setup!$C$4,4,5))=4,DATE(Setup!$C$4,4,5),"") | H4: =IF(MONTH(DATE(Setup!$C$4,4,6))=4,DATE(Setup!$C$4,4,6),"") | I4: =IF(MONTH(DATE(Setup!$C$4,4,7))=4,DATE(Setup!$C$4,4,7),"") | J4: =IF(MONTH(DATE(Setup!$C$4,4,8))=4,DATE(Setup!$C$4,4,8),"") | K4: =IF(MONTH(DATE(Setup!$C$4,4,9))=4,DATE(Setup!$C$4,4,9),"") | L4: =IF(MONTH(DATE(Setup!$C$4,4,10))=4,DATE(Setup!$C$4,4,10),"") | M4: =IF(MONTH(DATE(Setup!$C$4,4,11))=4,DATE(Setup!$C$4,4,11),"") | N4: =IF(MONTH(DATE(Setup!$C$4,4,12))=4,DATE(Setup!$C$4,4,12),"") | O4: =IF(MONTH(DATE(Setup!$C$4,4,13))=4,DATE(Setup!$C$4,4,13),"") | P4: =IF(MONTH(DATE(Setup!$C$4,4,14))=4,DATE(Setup!$C$4,4,14),"") | Q4: =IF(MONTH(DATE(Setup!$C$4,4,15))=4,DATE(Setup!$C$4,4,15),"") | R4: =IF(MONTH(DATE(Setup!$C$4,4,16))=4,DATE(Setup!$C$4,4,16),"") | S4: =IF(MONTH(DATE(Setup!$C$4,4,17))=4,DATE(Setup!$C$4,4,17),"") | T4: =IF(MONTH(DATE(Setup!$C$4,4,18))=4,DATE(Setup!$C$4,4,18),"") | U4: =IF(MONTH(DATE(Setup!$C$4,4,19))=4,DATE(Setup!$C$4,4,19),"") | V4: =IF(MONTH(DATE(Setup!$C$4,4,20))=4,DATE(Setup!$C$4,4,20),"") | W4: =IF(MONTH(DATE(Setup!$C$4,4,21))=4,DATE(Setup!$C$4,4,21),"") | X4: =IF(MONTH(DATE(Setup!$C$4,4,22))=4,DATE(Setup!$C$4,4,22),"") | Y4: =IF(MONTH(DATE(Setup!$C$4,4,23))=4,DATE(Setup!$C$4,4,23),"") | Z4: =IF(MONTH(DATE(Setup!$C$4,4,24))=4,DATE(Setup!$C$4,4,24),"") | AA4: =IF(MONTH(DATE(Setup!$C$4,4,25))=4,DATE(Setup!$C$4,4,25),"") | AB4: =IF(MONTH(DATE(Setup!$C$4,4,26))=4,DATE(Setup!$C$4,4,26),"") | AC4: =IF(MONTH(DATE(Setup!$C$4,4,27))=4,DATE(Setup!$C$4,4,27),"") | AD4: =IF(MONTH(DATE(Setup!$C$4,4,28))=4,DATE(Setup!$C$4,4,28),"") | AE4: =IF(MONTH(DATE(Setup!$C$4,4,29))=4,DATE(Setup!$C$4,4,29),"") | AF4: =IF(MONTH(DATE(Setup!$C$4,4,30))=4,DATE(Setup!$C$4,4,30),"") | AG4: =IF(MONTH(DATE(Setup!$C$4,4,31))=4,DATE(Setup!$C$4,4,31),"") | AH4: Done | AI4: Goal | AJ4: Rate | AK4: vs goal
C5: =IF(C4="","",MID("SMTWTFS",WEEKDAY(C4),1)) | D5: =IF(D4="","",MID("SMTWTFS",WEEKDAY(D4),1)) | E5: =IF(E4="","",MID("SMTWTFS",WEEKDAY(E4),1)) | F5: =IF(F4="","",MID("SMTWTFS",WEEKDAY(F4),1)) | G5: =IF(G4="","",MID("SMTWTFS",WEEKDAY(G4),1)) | H5: =IF(H4="","",MID("SMTWTFS",WEEKDAY(H4),1)) | I5: =IF(I4="","",MID("SMTWTFS",WEEKDAY(I4),1)) | J5: =IF(J4="","",MID("SMTWTFS",WEEKDAY(J4),1)) | ... AG5: =IF(AG4="","",MID("SMTWTFS",WEEKDAY(AG4),1))
B6: =IF(Setup!B7="","",Setup!B7) | AH6: =IF(B6="","",COUNTIF(C6:AG6,"✓")+COUNTIF(C6:AG6,"x")) | AI6: =IF(OR(B6="",Setup!C7=""),"",MIN(Setup!C7,COUNT($C$4:$AG$4))) | AJ6: =IF(B6="","",AH6/COUNT($C$4:$AG$4)) | AK6: =IF(OR(B6="",N(AI6)=0),"",MIN(1,AH6/AI6))
B7: =IF(Setup!B8="","",Setup!B8) | AH7: =IF(B7="","",COUNTIF(C7:AG7,"✓")+COUNTIF(C7:AG7,"x")) | AI7: =IF(OR(B7="",Setup!C8=""),"",MIN(Setup!C8,COUNT($C$4:$AG$4))) | AJ7: =IF(B7="","",AH7/COUNT($C$4:$AG$4)) | AK7: =IF(OR(B7="",N(AI7)=0),"",MIN(1,AH7/AI7))
B8: =IF(Setup!B9="","",Setup!B9) | AH8: =IF(B8="","",COUNTIF(C8:AG8,"✓")+COUNTIF(C8:AG8,"x")) | AI8: =IF(OR(B8="",Setup!C9=""),"",MIN(Setup!C9,COUNT($C$4:$AG$4))) | AJ8: =IF(B8="","",AH8/COUNT($C$4:$AG$4)) | AK8: =IF(OR(B8="",N(AI8)=0),"",MIN(1,AH8/AI8))
B9: =IF(Setup!B10="","",Setup!B10) | AH9: =IF(B9="","",COUNTIF(C9:AG9,"✓")+COUNTIF(C9:AG9,"x")) | AI9: =IF(OR(B9="",Setup!C10=""),"",MIN(Setup!C10,COUNT($C$4:$AG$4))) | AJ9: =IF(B9="","",AH9/COUNT($C$4:$AG$4)) | AK9: =IF(OR(B9="",N(AI9)=0),"",MIN(1,AH9/AI9))
B10: =IF(Setup!B11="","",Setup!B11) | AH10: =IF(B10="","",COUNTIF(C10:AG10,"✓")+COUNTIF(C10:AG10,"x")) | AI10: =IF(OR(B10="",Setup!C11=""),"",MIN(Setup!C11,COUNT($C$4:$AG$4))) | AJ10: =IF(B10="","",AH10/COUNT($C$4:$AG$4)) | AK10: =IF(OR(B10="",N(AI10)=0),"",MIN(1,AH10/AI10))
B11: =IF(Setup!B12="","",Setup!B12) | AH11: =IF(B11="","",COUNTIF(C11:AG11,"✓")+COUNTIF(C11:AG11,"x")) | AI11: =IF(OR(B11="",Setup!C12=""),"",MIN(Setup!C12,COUNT($C$4:$AG$4))) | AJ11: =IF(B11="","",AH11/COUNT($C$4:$AG$4)) | AK11: =IF(OR(B11="",N(AI11)=0),"",MIN(1,AH11/AI11))
B12: =IF(Setup!B13="","",Setup!B13) | AH12: =IF(B12="","",COUNTIF(C12:AG12,"✓")+COUNTIF(C12:AG12,"x")) | AI12: =IF(OR(B12="",Setup!C13=""),"",MIN(Setup!C13,COUNT($C$4:$AG$4))) | AJ12: =IF(B12="","",AH12/COUNT($C$4:$AG$4)) | AK12: =IF(OR(B12="",N(AI12)=0),"",MIN(1,AH12/AI12))
B13: =IF(Setup!B14="","",Setup!B14) | AH13: =IF(B13="","",COUNTIF(C13:AG13,"✓")+COUNTIF(C13:AG13,"x")) | AI13: =IF(OR(B13="",Setup!C14=""),"",MIN(Setup!C14,COUNT($C$4:$AG$4))) | AJ13: =IF(B13="","",AH13/COUNT($C$4:$AG$4)) | AK13: =IF(OR(B13="",N(AI13)=0),"",MIN(1,AH13/AI13))
B14: =IF(Setup!B15="","",Setup!B15) | AH14: =IF(B14="","",COUNTIF(C14:AG14,"✓")+COUNTIF(C14:AG14,"x")) | AI14: =IF(OR(B14="",Setup!C15=""),"",MIN(Setup!C15,COUNT($C$4:$AG$4))) | AJ14: =IF(B14="","",AH14/COUNT($C$4:$AG$4)) | AK14: =IF(OR(B14="",N(AI14)=0),"",MIN(1,AH14/AI14))
B15: =IF(Setup!B16="","",Setup!B16) | AH15: =IF(B15="","",COUNTIF(C15:AG15,"✓")+COUNTIF(C15:AG15,"x")) | AI15: =IF(OR(B15="",Setup!C16=""),"",MIN(Setup!C16,COUNT($C$4:$AG$4))) | AJ15: =IF(B15="","",AH15/COUNT($C$4:$AG$4)) | AK15: =IF(OR(B15="",N(AI15)=0),"",MIN(1,AH15/AI15))
B16: =IF(Setup!B17="","",Setup!B17) | AH16: =IF(B16="","",COUNTIF(C16:AG16,"✓")+COUNTIF(C16:AG16,"x")) | AI16: =IF(OR(B16="",Setup!C17=""),"",MIN(Setup!C17,COUNT($C$4:$AG$4))) | AJ16: =IF(B16="","",AH16/COUNT($C$4:$AG$4)) | AK16: =IF(OR(B16="",N(AI16)=0),"",MIN(1,AH16/AI16))
B17: =IF(Setup!B18="","",Setup!B18) | AH17: =IF(B17="","",COUNTIF(C17:AG17,"✓")+COUNTIF(C17:AG17,"x")) | AI17: =IF(OR(B17="",Setup!C18=""),"",MIN(Setup!C18,COUNT($C$4:$AG$4))) | AJ17: =IF(B17="","",AH17/COUNT($C$4:$AG$4)) | AK17: =IF(OR(B17="",N(AI17)=0),"",MIN(1,AH17/AI17))
... B20: =IF(Setup!B21="","",Setup!B21) | AH20: =IF(B20="","",COUNTIF(C20:AG20,"✓")+COUNTIF(C20:AG20,"x")) | AI20: =IF(OR(B20="",Setup!C21=""),"",MIN(Setup!C21,COUNT($C$4:$AG$4))) | AJ20: =IF(B20="","",AH20/COUNT($C$4:$AG$4)) | AK20: =IF(OR(B20="",N(AI20)=0),"",MIN(1,AH20/AI20))
B21: Day complete | C21: =IF(OR(C4="",COUNTIF($B$6:$B$20,"?*")=0),"",(COUNTIF(C6:C20,"✓")+COUNTIF(C6:C20,"x"))/COUNTIF($B$6:$B$20,"?*")) | D21: =IF(OR(D4="",COUNTIF($B$6:$B$20,"?*")=0),"",(COUNTIF(D6:D20,"✓")+COUNTIF(D6:D20,"x"))/COUNTIF($B$6:$B$20,"?*")) | E21: =IF(OR(E4="",COUNTIF($B$6:$B$20,"?*")=0),"",(COUNTIF(E6:E20,"✓")+COUNTIF(E6:E20,"x"))/COUNTIF($B$6:$B$20,"?*")) | F21: =IF(OR(F4="",COUNTIF($B$6:$B$20,"?*")=0),"",(COUNTIF(F6:F20,"✓")+COUNTIF(F6:F20,"x"))/COUNTIF($B$6:$B$20,"?*")) | G21: =IF(OR(G4="",COUNTIF($B$6:$B$20,"?*")=0),"",(COUNTIF(G6:G20,"✓")+COUNTIF(G6:G20,"x"))/COUNTIF($B$6:$B$20,"?*")) | H21: =IF(OR(H4="",COUNTIF($B$6:$B$20,"?*")=0),"",(COUNTIF(H6:H20,"✓")+COUNTIF(H6:H20,"x"))/COUNTIF($B$6:$B$20,"?*")) | I21: =IF(OR(I4="",COUNTIF($B$6:$B$20,"?*")=0),"",(COUNTIF(I6:I20,"✓")+COUNTIF(I6:I20,"x"))/COUNTIF($B$6:$B$20,"?*")) | J21: =IF(OR(J4="",COUNTIF($B$6:$B$20,"?*")=0),"",(COUNTIF(J6:J20,"✓")+COUNTIF(J6:J20,"x"))/COUNTIF($B$6:$B$20,"?*")) | ... AG21: =IF(OR(AG4="",COUNTIF($B$6:$B$20,"?*")=0),"",(COUNTIF(AG6:AG20,"✓")+COUNTIF(AG6:AG20,"x"))/COUNTIF($B$6:$B$20,"?*")) | AJ21: =IFERROR(AVERAGE(AJ6:AJ20),"")

Sheet May
A1: =TEXT(DATE(Setup!$C$4,5,1),"mmmm yyyy")
A2: Mark ✓ when done · علّم ✓ عند الإنجاز
B4: Habit | C4: =IF(MONTH(DATE(Setup!$C$4,5,1))=5,DATE(Setup!$C$4,5,1),"") | D4: =IF(MONTH(DATE(Setup!$C$4,5,2))=5,DATE(Setup!$C$4,5,2),"") | E4: =IF(MONTH(DATE(Setup!$C$4,5,3))=5,DATE(Setup!$C$4,5,3),"") | F4: =IF(MONTH(DATE(Setup!$C$4,5,4))=5,DATE(Setup!$C$4,5,4),"") | G4: =IF(MONTH(DATE(Setup!$C$4,5,5))=5,DATE(Setup!$C$4,5,5),"") | H4: =IF(MONTH(DATE(Setup!$C$4,5,6))=5,DATE(Setup!$C$4,5,6),"") | I4: =IF(MONTH(DATE(Setup!$C$4,5,7))=5,DATE(Setup!$C$4,5,7),"") | J4: =IF(MONTH(DATE(Setup!$C$4,5,8))=5,DATE(Setup!$C$4,5,8),"") | K4: =IF(MONTH(DATE(Setup!$C$4,5,9))=5,DATE(Setup!$C$4,5,9),"") | L4: =IF(MONTH(DATE(Setup!$C$4,5,10))=5,DATE(Setup!$C$4,5,10),"") | M4: =IF(MONTH(DATE(Setup!$C$4,5,11))=5,DATE(Setup!$C$4,5,11),"") | N4: =IF(MONTH(DATE(Setup!$C$4,5,12))=5,DATE(Setup!$C$4,5,12),"") | O4: =IF(MONTH(DATE(Setup!$C$4,5,13))=5,DATE(Setup!$C$4,5,13),"") | P4: =IF(MONTH(DATE(Setup!$C$4,5,14))=5,DATE(Setup!$C$4,5,14),"") | Q4: =IF(MONTH(DATE(Setup!$C$4,5,15))=5,DATE(Setup!$C$4,5,15),"") | R4: =IF(MONTH(DATE(Setup!$C$4,5,16))=5,DATE(Setup!$C$4,5,16),"") | S4: =IF(MONTH(DATE(Setup!$C$4,5,17))=5,DATE(Setup!$C$4,5,17),"") | T4: =IF(MONTH(DATE(Setup!$C$4,5,18))=5,DATE(Setup!$C$4,5,18),"") | U4: =IF(MONTH(DATE(Setup!$C$4,5,19))=5,DATE(Setup!$C$4,5,19),"") | V4: =IF(MONTH(DATE(Setup!$C$4,5,20))=5,DATE(Setup!$C$4,5,20),"") | W4: =IF(MONTH(DATE(Setup!$C$4,5,21))=5,DATE(Setup!$C$4,5,21),"") | X4: =IF(MONTH(DATE(Setup!$C$4,5,22))=5,DATE(Setup!$C$4,5,22),"") | Y4: =IF(MONTH(DATE(Setup!$C$4,5,23))=5,DATE(Setup!$C$4,5,23),"") | Z4: =IF(MONTH(DATE(Setup!$C$4,5,24))=5,DATE(Setup!$C$4,5,24),"") | AA4: =IF(MONTH(DATE(Setup!$C$4,5,25))=5,DATE(Setup!$C$4,5,25),"") | AB4: =IF(MONTH(DATE(Setup!$C$4,5,26))=5,DATE(Setup!$C$4,5,26),"") | AC4: =IF(MONTH(DATE(Setup!$C$4,5,27))=5,DATE(Setup!$C$4,5,27),"") | AD4: =IF(MONTH(DATE(Setup!$C$4,5,28))=5,DATE(Setup!$C$4,5,28),"") | AE4: =IF(MONTH(DATE(Setup!$C$4,5,29))=5,DATE(Setup!$C$4,5,29),"") | AF4: =IF(MONTH(DATE(Setup!$C$4,5,30))=5,DATE(Setup!$C$4,5,30),"") | AG4: =IF(MONTH(DATE(Setup!$C$4,5,31))=5,DATE(Setup!$C$4,5,31),"") | AH4: Done | AI4: Goal | AJ4: Rate | AK4: vs goal
C5: =IF(C4="","",MID("SMTWTFS",WEEKDAY(C4),1)) | D5: =IF(D4="","",MID("SMTWTFS",WEEKDAY(D4),1)) | E5: =IF(E4="","",MID("SMTWTFS",WEEKDAY(E4),1)) | F5: =IF(F4="","",MID("SMTWTFS",WEEKDAY(F4),1)) | G5: =IF(G4="","",MID("SMTWTFS",WEEKDAY(G4),1)) | H5: =IF(H4="","",MID("SMTWTFS",WEEKDAY(H4),1)) | I5: =IF(I4="","",MID("SMTWTFS",WEEKDAY(I4),1)) | J5: =IF(J4="","",MID("SMTWTFS",WEEKDAY(J4),1)) | ... AG5: =IF(AG4="","",MID("SMTWTFS",WEEKDAY(AG4),1))
B6: =IF(Setup!B7="","",Setup!B7) | AH6: =IF(B6="","",COUNTIF(C6:AG6,"✓")+COUNTIF(C6:AG6,"x")) | AI6: =IF(OR(B6="",Setup!C7=""),"",MIN(Setup!C7,COUNT($C$4:$AG$4))) | AJ6: =IF(B6="","",AH6/COUNT($C$4:$AG$4)) | AK6: =IF(OR(B6="",N(AI6)=0),"",MIN(1,AH6/AI6))
B7: =IF(Setup!B8="","",Setup!B8) | AH7: =IF(B7="","",COUNTIF(C7:AG7,"✓")+COUNTIF(C7:AG7,"x")) | AI7: =IF(OR(B7="",Setup!C8=""),"",MIN(Setup!C8,COUNT($C$4:$AG$4))) | AJ7: =IF(B7="","",AH7/COUNT($C$4:$AG$4)) | AK7: =IF(OR(B7="",N(AI7)=0),"",MIN(1,AH7/AI7))
B8: =IF(Setup!B9="","",Setup!B9) | AH8: =IF(B8="","",COUNTIF(C8:AG8,"✓")+COUNTIF(C8:AG8,"x")) | AI8: =IF(OR(B8="",Setup!C9=""),"",MIN(Setup!C9,COUNT($C$4:$AG$4))) | AJ8: =IF(B8="","",AH8/COUNT($C$4:$AG$4)) | AK8: =IF(OR(B8="",N(AI8)=0),"",MIN(1,AH8/AI8))
B9: =IF(Setup!B10="","",Setup!B10) | AH9: =IF(B9="","",COUNTIF(C9:AG9,"✓")+COUNTIF(C9:AG9,"x")) | AI9: =IF(OR(B9="",Setup!C10=""),"",MIN(Setup!C10,COUNT($C$4:$AG$4))) | AJ9: =IF(B9="","",AH9/COUNT($C$4:$AG$4)) | AK9: =IF(OR(B9="",N(AI9)=0),"",MIN(1,AH9/AI9))
B10: =IF(Setup!B11="","",Setup!B11) | AH10: =IF(B10="","",COUNTIF(C10:AG10,"✓")+COUNTIF(C10:AG10,"x")) | AI10: =IF(OR(B10="",Setup!C11=""),"",MIN(Setup!C11,COUNT($C$4:$AG$4))) | AJ10: =IF(B10="","",AH10/COUNT($C$4:$AG$4)) | AK10: =IF(OR(B10="",N(AI10)=0),"",MIN(1,AH10/AI10))
B11: =IF(Setup!B12="","",Setup!B12) | AH11: =IF(B11="","",COUNTIF(C11:AG11,"✓")+COUNTIF(C11:AG11,"x")) | AI11: =IF(OR(B11="",Setup!C12=""),"",MIN(Setup!C12,COUNT($C$4:$AG$4))) | AJ11: =IF(B11="","",AH11/COUNT($C$4:$AG$4)) | AK11: =IF(OR(B11="",N(AI11)=0),"",MIN(1,AH11/AI11))
B12: =IF(Setup!B13="","",Setup!B13) | AH12: =IF(B12="","",COUNTIF(C12:AG12,"✓")+COUNTIF(C12:AG12,"x")) | AI12: =IF(OR(B12="",Setup!C13=""),"",MIN(Setup!C13,COUNT($C$4:$AG$4))) | AJ12: =IF(B12="","",AH12/COUNT($C$4:$AG$4)) | AK12: =IF(OR(B12="",N(AI12)=0),"",MIN(1,AH12/AI12))
B13: =IF(Setup!B14="","",Setup!B14) | AH13: =IF(B13="","",COUNTIF(C13:AG13,"✓")+COUNTIF(C13:AG13,"x")) | AI13: =IF(OR(B13="",Setup!C14=""),"",MIN(Setup!C14,COUNT($C$4:$AG$4))) | AJ13: =IF(B13="","",AH13/COUNT($C$4:$AG$4)) | AK13: =IF(OR(B13="",N(AI13)=0),"",MIN(1,AH13/AI13))
B14: =IF(Setup!B15="","",Setup!B15) | AH14: =IF(B14="","",COUNTIF(C14:AG14,"✓")+COUNTIF(C14:AG14,"x")) | AI14: =IF(OR(B14="",Setup!C15=""),"",MIN(Setup!C15,COUNT($C$4:$AG$4))) | AJ14: =IF(B14="","",AH14/COUNT($C$4:$AG$4)) | AK14: =IF(OR(B14="",N(AI14)=0),"",MIN(1,AH14/AI14))
B15: =IF(Setup!B16="","",Setup!B16) | AH15: =IF(B15="","",COUNTIF(C15:AG15,"✓")+COUNTIF(C15:AG15,"x")) | AI15: =IF(OR(B15="",Setup!C16=""),"",MIN(Setup!C16,COUNT($C$4:$AG$4))) | AJ15: =IF(B15="","",AH15/COUNT($C$4:$AG$4)) | AK15: =IF(OR(B15="",N(AI15)=0),"",MIN(1,AH15/AI15))
B16: =IF(Setup!B17="","",Setup!B17) | AH16: =IF(B16="","",COUNTIF(C16:AG16,"✓")+COUNTIF(C16:AG16,"x")) | AI16: =IF(OR(B16="",Setup!C17=""),"",MIN(Setup!C17,COUNT($C$4:$AG$4))) | AJ16: =IF(B16="","",AH16/COUNT($C$4:$AG$4)) | AK16: =IF(OR(B16="",N(AI16)=0),"",MIN(1,AH16/AI16))
B17: =IF(Setup!B18="","",Setup!B18) | AH17: =IF(B17="","",COUNTIF(C17:AG17,"✓")+COUNTIF(C17:AG17,"x")) | AI17: =IF(OR(B17="",Setup!C18=""),"",MIN(Setup!C18,COUNT($C$4:$AG$4))) | AJ17: =IF(B17="","",AH17/COUNT($C$4:$AG$4)) | AK17: =IF(OR(B17="",N(AI17)=0),"",MIN(1,AH17/AI17))
... B20: =IF(Setup!B21="","",Setup!B21) | AH20: =IF(B20="","",COUNTIF(C20:AG20,"✓")+COUNTIF(C20:AG20,"x")) | AI20: =IF(OR(B20="",Setup!C21=""),"",MIN(Setup!C21,COUNT($C$4:$AG$4))) | AJ20: =IF(B20="","",AH20/COUNT($C$4:$AG$4)) | AK20: =IF(OR(B20="",N(AI20)=0),"",MIN(1,AH20/AI20))
B21: Day complete | C21: =IF(OR(C4="",COUNTIF($B$6:$B$20,"?*")=0),"",(COUNTIF(C6:C20,"✓")+COUNTIF(C6:C20,"x"))/COUNTIF($B$6:$B$20,"?*")) | D21: =IF(OR(D4="",COUNTIF($B$6:$B$20,"?*")=0),"",(COUNTIF(D6:D20,"✓")+COUNTIF(D6:D20,"x"))/COUNTIF($B$6:$B$20,"?*")) | E21: =IF(OR(E4="",COUNTIF($B$6:$B$20,"?*")=0),"",(COUNTIF(E6:E20,"✓")+COUNTIF(E6:E20,"x"))/COUNTIF($B$6:$B$20,"?*")) | F21: =IF(OR(F4="",COUNTIF($B$6:$B$20,"?*")=0),"",(COUNTIF(F6:F20,"✓")+COUNTIF(F6:F20,"x"))/COUNTIF($B$6:$B$20,"?*")) | G21: =IF(OR(G4="",COUNTIF($B$6:$B$20,"?*")=0),"",(COUNTIF(G6:G20,"✓")+COUNTIF(G6:G20,"x"))/COUNTIF($B$6:$B$20,"?*")) | H21: =IF(OR(H4="",COUNTIF($B$6:$B$20,"?*")=0),"",(COUNTIF(H6:H20,"✓")+COUNTIF(H6:H20,"x"))/COUNTIF($B$6:$B$20,"?*")) | I21: =IF(OR(I4="",COUNTIF($B$6:$B$20,"?*")=0),"",(COUNTIF(I6:I20,"✓")+COUNTIF(I6:I20,"x"))/COUNTIF($B$6:$B$20,"?*")) | J21: =IF(OR(J4="",COUNTIF($B$6:$B$20,"?*")=0),"",(COUNTIF(J6:J20,"✓")+COUNTIF(J6:J20,"x"))/COUNTIF($B$6:$B$20,"?*")) | ... AG21: =IF(OR(AG4="",COUNTIF($B$6:$B$20,"?*")=0),"",(COUNTIF(AG6:AG20,"✓")+COUNTIF(AG6:AG20,"x"))/COUNTIF($B$6:$B$20,"?*")) | AJ21: =IFERROR(AVERAGE(AJ6:AJ20),"")

Sheet Jun
A1: =TEXT(DATE(Setup!$C$4,6,1),"mmmm yyyy")
A2: Mark ✓ when done · علّم ✓ عند الإنجاز
B4: Habit | C4: =IF(MONTH(DATE(Setup!$C$4,6,1))=6,DATE(Setup!$C$4,6,1),"") | D4: =IF(MONTH(DATE(Setup!$C$4,6,2))=6,DATE(Setup!$C$4,6,2),"") | E4: =IF(MONTH(DATE(Setup!$C$4,6,3))=6,DATE(Setup!$C$4,6,3),"") | F4: =IF(MONTH(DATE(Setup!$C$4,6,4))=6,DATE(Setup!$C$4,6,4),"") | G4: =IF(MONTH(DATE(Setup!$C$4,6,5))=6,DATE(Setup!$C$4,6,5),"") | H4: =IF(MONTH(DATE(Setup!$C$4,6,6))=6,DATE(Setup!$C$4,6,6),"") | I4: =IF(MONTH(DATE(Setup!$C$4,6,7))=6,DATE(Setup!$C$4,6,7),"") | J4: =IF(MONTH(DATE(Setup!$C$4,6,8))=6,DATE(Setup!$C$4,6,8),"") | K4: =IF(MONTH(DATE(Setup!$C$4,6,9))=6,DATE(Setup!$C$4,6,9),"") | L4: =IF(MONTH(DATE(Setup!$C$4,6,10))=6,DATE(Setup!$C$4,6,10),"") | M4: =IF(MONTH(DATE(Setup!$C$4,6,11))=6,DATE(Setup!$C$4,6,11),"") | N4: =IF(MONTH(DATE(Setup!$C$4,6,12))=6,DATE(Setup!$C$4,6,12),"") | O4: =IF(MONTH(DATE(Setup!$C$4,6,13))=6,DATE(Setup!$C$4,6,13),"") | P4: =IF(MONTH(DATE(Setup!$C$4,6,14))=6,DATE(Setup!$C$4,6,14),"") | Q4: =IF(MONTH(DATE(Setup!$C$4,6,15))=6,DATE(Setup!$C$4,6,15),"") | R4: =IF(MONTH(DATE(Setup!$C$4,6,16))=6,DATE(Setup!$C$4,6,16),"") | S4: =IF(MONTH(DATE(Setup!$C$4,6,17))=6,DATE(Setup!$C$4,6,17),"") | T4: =IF(MONTH(DATE(Setup!$C$4,6,18))=6,DATE(Setup!$C$4,6,18),"") | U4: =IF(MONTH(DATE(Setup!$C$4,6,19))=6,DATE(Setup!$C$4,6,19),"") | V4: =IF(MONTH(DATE(Setup!$C$4,6,20))=6,DATE(Setup!$C$4,6,20),"") | W4: =IF(MONTH(DATE(Setup!$C$4,6,21))=6,DATE(Setup!$C$4,6,21),"") | X4: =IF(MONTH(DATE(Setup!$C$4,6,22))=6,DATE(Setup!$C$4,6,22),"") | Y4: =IF(MONTH(DATE(Setup!$C$4,6,23))=6,DATE(Setup!$C$4,6,23),"") | Z4: =IF(MONTH(DATE(Setup!$C$4,6,24))=6,DATE(Setup!$C$4,6,24),"") | AA4: =IF(MONTH(DATE(Setup!$C$4,6,25))=6,DATE(Setup!$C$4,6,25),"") | AB4: =IF(MONTH(DATE(Setup!$C$4,6,26))=6,DATE(Setup!$C$4,6,26),"") | AC4: =IF(MONTH(DATE(Setup!$C$4,6,27))=6,DATE(Setup!$C$4,6,27),"") | AD4: =IF(MONTH(DATE(Setup!$C$4,6,28))=6,DATE(Setup!$C$4,6,28),"") | AE4: =IF(MONTH(DATE(Setup!$C$4,6,29))=6,DATE(Setup!$C$4,6,29),"") | AF4: =IF(MONTH(DATE(Setup!$C$4,6,30))=6,DATE(Setup!$C$4,6,30),"") | AG4: =IF(MONTH(DATE(Setup!$C$4,6,31))=6,DATE(Setup!$C$4,6,31),"") | AH4: Done | AI4: Goal | AJ4: Rate | AK4: vs goal
C5: =IF(C4="","",MID("SMTWTFS",WEEKDAY(C4),1)) | D5: =IF(D4="","",MID("SMTWTFS",WEEKDAY(D4),1)) | E5: =IF(E4="","",MID("SMTWTFS",WEEKDAY(E4),1)) | F5: =IF(F4="","",MID("SMTWTFS",WEEKDAY(F4),1)) | G5: =IF(G4="","",MID("SMTWTFS",WEEKDAY(G4),1)) | H5: =IF(H4="","",MID("SMTWTFS",WEEKDAY(H4),1)) | I5: =IF(I4="","",MID("SMTWTFS",WEEKDAY(I4),1)) | J5: =IF(J4="","",MID("SMTWTFS",WEEKDAY(J4),1)) | ... AG5: =IF(AG4="","",MID("SMTWTFS",WEEKDAY(AG4),1))
B6: =IF(Setup!B7="","",Setup!B7) | AH6: =IF(B6="","",COUNTIF(C6:AG6,"✓")+COUNTIF(C6:AG6,"x")) | AI6: =IF(OR(B6="",Setup!C7=""),"",MIN(Setup!C7,COUNT($C$4:$AG$4))) | AJ6: =IF(B6="","",AH6/COUNT($C$4:$AG$4)) | AK6: =IF(OR(B6="",N(AI6)=0),"",MIN(1,AH6/AI6))
B7: =IF(Setup!B8="","",Setup!B8) | AH7: =IF(B7="","",COUNTIF(C7:AG7,"✓")+COUNTIF(C7:AG7,"x")) | AI7: =IF(OR(B7="",Setup!C8=""),"",MIN(Setup!C8,COUNT($C$4:$AG$4))) | AJ7: =IF(B7="","",AH7/COUNT($C$4:$AG$4)) | AK7: =IF(OR(B7="",N(AI7)=0),"",MIN(1,AH7/AI7))
B8: =IF(Setup!B9="","",Setup!B9) | AH8: =IF(B8="","",COUNTIF(C8:AG8,"✓")+COUNTIF(C8:AG8,"x")) | AI8: =IF(OR(B8="",Setup!C9=""),"",MIN(Setup!C9,COUNT($C$4:$AG$4))) | AJ8: =IF(B8="","",AH8/COUNT($C$4:$AG$4)) | AK8: =IF(OR(B8="",N(AI8)=0),"",MIN(1,AH8/AI8))
B9: =IF(Setup!B10="","",Setup!B10) | AH9: =IF(B9="","",COUNTIF(C9:AG9,"✓")+COUNTIF(C9:AG9,"x")) | AI9: =IF(OR(B9="",Setup!C10=""),"",MIN(Setup!C10,COUNT($C$4:$AG$4))) | AJ9: =IF(B9="","",AH9/COUNT($C$4:$AG$4)) | AK9: =IF(OR(B9="",N(AI9)=0),"",MIN(1,AH9/AI9))
B10: =IF(Setup!B11="","",Setup!B11) | AH10: =IF(B10="","",COUNTIF(C10:AG10,"✓")+COUNTIF(C10:AG10,"x")) | AI10: =IF(OR(B10="",Setup!C11=""),"",MIN(Setup!C11,COUNT($C$4:$AG$4))) | AJ10: =IF(B10="","",AH10/COUNT($C$4:$AG$4)) | AK10: =IF(OR(B10="",N(AI10)=0),"",MIN(1,AH10/AI10))
B11: =IF(Setup!B12="","",Setup!B12) | AH11: =IF(B11="","",COUNTIF(C11:AG11,"✓")+COUNTIF(C11:AG11,"x")) | AI11: =IF(OR(B11="",Setup!C12=""),"",MIN(Setup!C12,COUNT($C$4:$AG$4))) | AJ11: =IF(B11="","",AH11/COUNT($C$4:$AG$4)) | AK11: =IF(OR(B11="",N(AI11)=0),"",MIN(1,AH11/AI11))
B12: =IF(Setup!B13="","",Setup!B13) | AH12: =IF(B12="","",COUNTIF(C12:AG12,"✓")+COUNTIF(C12:AG12,"x")) | AI12: =IF(OR(B12="",Setup!C13=""),"",MIN(Setup!C13,COUNT($C$4:$AG$4))) | AJ12: =IF(B12="","",AH12/COUNT($C$4:$AG$4)) | AK12: =IF(OR(B12="",N(AI12)=0),"",MIN(1,AH12/AI12))
B13: =IF(Setup!B14="","",Setup!B14) | AH13: =IF(B13="","",COUNTIF(C13:AG13,"✓")+COUNTIF(C13:AG13,"x")) | AI13: =IF(OR(B13="",Setup!C14=""),"",MIN(Setup!C14,COUNT($C$4:$AG$4))) | AJ13: =IF(B13="","",AH13/COUNT($C$4:$AG$4)) | AK13: =IF(OR(B13="",N(AI13)=0),"",MIN(1,AH13/AI13))
B14: =IF(Setup!B15="","",Setup!B15) | AH14: =IF(B14="","",COUNTIF(C14:AG14,"✓")+COUNTIF(C14:AG14,"x")) | AI14: =IF(OR(B14="",Setup!C15=""),"",MIN(Setup!C15,COUNT($C$4:$AG$4))) | AJ14: =IF(B14="","",AH14/COUNT($C$4:$AG$4)) | AK14: =IF(OR(B14="",N(AI14)=0),"",MIN(1,AH14/AI14))
B15: =IF(Setup!B16="","",Setup!B16) | AH15: =IF(B15="","",COUNTIF(C15:AG15,"✓")+COUNTIF(C15:AG15,"x")) | AI15: =IF(OR(B15="",Setup!C16=""),"",MIN(Setup!C16,COUNT($C$4:$AG$4))) | AJ15: =IF(B15="","",AH15/COUNT($C$4:$AG$4)) | AK15: =IF(OR(B15="",N(AI15)=0),"",MIN(1,AH15/AI15))
B16: =IF(Setup!B17="","",Setup!B17) | AH16: =IF(B16="","",COUNTIF(C16:AG16,"✓")+COUNTIF(C16:AG16,"x")) | AI16: =IF(OR(B16="",Setup!C17=""),"",MIN(Setup!C17,COUNT($C$4:$AG$4))) | AJ16: =IF(B16="","",AH16/COUNT($C$4:$AG$4)) | AK16: =IF(OR(B16="",N(AI16)=0),"",MIN(1,AH16/AI16))
B17: =IF(Setup!B18="","",Setup!B18) | AH17: =IF(B17="","",COUNTIF(C17:AG17,"✓")+COUNTIF(C17:AG17,"x")) | AI17: =IF(OR(B17="",Setup!C18=""),"",MIN(Setup!C18,COUNT($C$4:$AG$4))) | AJ17: =IF(B17="","",AH17/COUNT($C$4:$AG$4)) | AK17: =IF(OR(B17="",N(AI17)=0),"",MIN(1,AH17/AI17))
... B20: =IF(Setup!B21="","",Setup!B21) | AH20: =IF(B20="","",COUNTIF(C20:AG20,"✓")+COUNTIF(C20:AG20,"x")) | AI20: =IF(OR(B20="",Setup!C21=""),"",MIN(Setup!C21,COUNT($C$4:$AG$4))) | AJ20: =IF(B20="","",AH20/COUNT($C$4:$AG$4)) | AK20: =IF(OR(B20="",N(AI20)=0),"",MIN(1,AH20/AI20))
B21: Day complete | C21: =IF(OR(C4="",COUNTIF($B$6:$B$20,"?*")=0),"",(COUNTIF(C6:C20,"✓")+COUNTIF(C6:C20,"x"))/COUNTIF($B$6:$B$20,"?*")) | D21: =IF(OR(D4="",COUNTIF($B$6:$B$20,"?*")=0),"",(COUNTIF(D6:D20,"✓")+COUNTIF(D6:D20,"x"))/COUNTIF($B$6:$B$20,"?*")) | E21: =IF(OR(E4="",COUNTIF($B$6:$B$20,"?*")=0),"",(COUNTIF(E6:E20,"✓")+COUNTIF(E6:E20,"x"))/COUNTIF($B$6:$B$20,"?*")) | F21: =IF(OR(F4="",COUNTIF($B$6:$B$20,"?*")=0),"",(COUNTIF(F6:F20,"✓")+COUNTIF(F6:F20,"x"))/COUNTIF($B$6:$B$20,"?*")) | G21: =IF(OR(G4="",COUNTIF($B$6:$B$20,"?*")=0),"",(COUNTIF(G6:G20,"✓")+COUNTIF(G6:G20,"x"))/COUNTIF($B$6:$B$20,"?*")) | H21: =IF(OR(H4="",COUNTIF($B$6:$B$20,"?*")=0),"",(COUNTIF(H6:H20,"✓")+COUNTIF(H6:H20,"x"))/COUNTIF($B$6:$B$20,"?*")) | I21: =IF(OR(I4="",COUNTIF($B$6:$B$20,"?*")=0),"",(COUNTIF(I6:I20,"✓")+COUNTIF(I6:I20,"x"))/COUNTIF($B$6:$B$20,"?*")) | J21: =IF(OR(J4="",COUNTIF($B$6:$B$20,"?*")=0),"",(COUNTIF(J6:J20,"✓")+COUNTIF(J6:J20,"x"))/COUNTIF($B$6:$B$20,"?*")) | ... AG21: =IF(OR(AG4="",COUNTIF($B$6:$B$20,"?*")=0),"",(COUNTIF(AG6:AG20,"✓")+COUNTIF(AG6:AG20,"x"))/COUNTIF($B$6:$B$20,"?*")) | AJ21: =IFERROR(AVERAGE(AJ6:AJ20),"")

Sheet Jul
A1: =TEXT(DATE(Setup!$C$4,7,1),"mmmm yyyy")
A2: Mark ✓ when done · علّم ✓ عند الإنجاز
B4: Habit | C4: =IF(MONTH(DATE(Setup!$C$4,7,1))=7,DATE(Setup!$C$4,7,1),"") | D4: =IF(MONTH(DATE(Setup!$C$4,7,2))=7,DATE(Setup!$C$4,7,2),"") | E4: =IF(MONTH(DATE(Setup!$C$4,7,3))=7,DATE(Setup!$C$4,7,3),"") | F4: =IF(MONTH(DATE(Setup!$C$4,7,4))=7,DATE(Setup!$C$4,7,4),"") | G4: =IF(MONTH(DATE(Setup!$C$4,7,5))=7,DATE(Setup!$C$4,7,5),"") | H4: =IF(MONTH(DATE(Setup!$C$4,7,6))=7,DATE(Setup!$C$4,7,6),"") | I4: =IF(MONTH(DATE(Setup!$C$4,7,7))=7,DATE(Setup!$C$4,7,7),"") | J4: =IF(MONTH(DATE(Setup!$C$4,7,8))=7,DATE(Setup!$C$4,7,8),"") | K4: =IF(MONTH(DATE(Setup!$C$4,7,9))=7,DATE(Setup!$C$4,7,9),"") | L4: =IF(MONTH(DATE(Setup!$C$4,7,10))=7,DATE(Setup!$C$4,7,10),"") | M4: =IF(MONTH(DATE(Setup!$C$4,7,11))=7,DATE(Setup!$C$4,7,11),"") | N4: =IF(MONTH(DATE(Setup!$C$4,7,12))=7,DATE(Setup!$C$4,7,12),"") | O4: =IF(MONTH(DATE(Setup!$C$4,7,13))=7,DATE(Setup!$C$4,7,13),"") | P4: =IF(MONTH(DATE(Setup!$C$4,7,14))=7,DATE(Setup!$C$4,7,14),"") | Q4: =IF(MONTH(DATE(Setup!$C$4,7,15))=7,DATE(Setup!$C$4,7,15),"") | R4: =IF(MONTH(DATE(Setup!$C$4,7,16))=7,DATE(Setup!$C$4,7,16),"") | S4: =IF(MONTH(DATE(Setup!$C$4,7,17))=7,DATE(Setup!$C$4,7,17),"") | T4: =IF(MONTH(DATE(Setup!$C$4,7,18))=7,DATE(Setup!$C$4,7,18),"") | U4: =IF(MONTH(DATE(Setup!$C$4,7,19))=7,DATE(Setup!$C$4,7,19),"") | V4: =IF(MONTH(DATE(Setup!$C$4,7,20))=7,DATE(Setup!$C$4,7,20),"") | W4: =IF(MONTH(DATE(Setup!$C$4,7,21))=7,DATE(Setup!$C$4,7,21),"") | X4: =IF(MONTH(DATE(Setup!$C$4,7,22))=7,DATE(Setup!$C$4,7,22),"") | Y4: =IF(MONTH(DATE(Setup!$C$4,7,23))=7,DATE(Setup!$C$4,7,23),"") | Z4: =IF(MONTH(DATE(Setup!$C$4,7,24))=7,DATE(Setup!$C$4,7,24),"") | AA4: =IF(MONTH(DATE(Setup!$C$4,7,25))=7,DATE(Setup!$C$4,7,25),"") | AB4: =IF(MONTH(DATE(Setup!$C$4,7,26))=7,DATE(Setup!$C$4,7,26),"") | AC4: =IF(MONTH(DATE(Setup!$C$4,7,27))=7,DATE(Setup!$C$4,7,27),"") | AD4: =IF(MONTH(DATE(Setup!$C$4,7,28))=7,DATE(Setup!$C$4,7,28),"") | AE4: =IF(MONTH(DATE(Setup!$C$4,7,29))=7,DATE(Setup!$C$4,7,29),"") | AF4: =IF(MONTH(DATE(Setup!$C$4,7,30))=7,DATE(Setup!$C$4,7,30),"") | AG4: =IF(MONTH(DATE(Setup!$C$4,7,31))=7,DATE(Setup!$C$4,7,31),"") | AH4: Done | AI4: Goal | AJ4: Rate | AK4: vs goal
C5: =IF(C4="","",MID("SMTWTFS",WEEKDAY(C4),1)) | D5: =IF(D4="","",MID("SMTWTFS",WEEKDAY(D4),1)) | E5: =IF(E4="","",MID("SMTWTFS",WEEKDAY(E4),1)) | F5: =IF(F4="","",MID("SMTWTFS",WEEKDAY(F4),1)) | G5: =IF(G4="","",MID("SMTWTFS",WEEKDAY(G4),1)) | H5: =IF(H4="","",MID("SMTWTFS",WEEKDAY(H4),1)) | I5: =IF(I4="","",MID("SMTWTFS",WEEKDAY(I4),1)) | J5: =IF(J4="","",MID("SMTWTFS",WEEKDAY(J4),1)) | ... AG5: =IF(AG4="","",MID("SMTWTFS",WEEKDAY(AG4),1))
B6: =IF(Setup!B7="","",Setup!B7) | AH6: =IF(B6="","",COUNTIF(C6:AG6,"✓")+COUNTIF(C6:AG6,"x")) | AI6: =IF(OR(B6="",Setup!C7=""),"",MIN(Setup!C7,COUNT($C$4:$AG$4))) | AJ6: =IF(B6="","",AH6/COUNT($C$4:$AG$4)) | AK6: =IF(OR(B6="",N(AI6)=0),"",MIN(1,AH6/AI6))
B7: =IF(Setup!B8="","",Setup!B8) | AH7: =IF(B7="","",COUNTIF(C7:AG7,"✓")+COUNTIF(C7:AG7,"x")) | AI7: =IF(OR(B7="",Setup!C8=""),"",MIN(Setup!C8,COUNT($C$4:$AG$4))) | AJ7: =IF(B7="","",AH7/COUNT($C$4:$AG$4)) | AK7: =IF(OR(B7="",N(AI7)=0),"",MIN(1,AH7/AI7))
B8: =IF(Setup!B9="","",Setup!B9) | AH8: =IF(B8="","",COUNTIF(C8:AG8,"✓")+COUNTIF(C8:AG8,"x")) | AI8: =IF(OR(B8="",Setup!C9=""),"",MIN(Setup!C9,COUNT($C$4:$AG$4))) | AJ8: =IF(B8="","",AH8/COUNT($C$4:$AG$4)) | AK8: =IF(OR(B8="",N(AI8)=0),"",MIN(1,AH8/AI8))
B9: =IF(Setup!B10="","",Setup!B10) | AH9: =IF(B9="","",COUNTIF(C9:AG9,"✓")+COUNTIF(C9:AG9,"x")) | AI9: =IF(OR(B9="",Setup!C10=""),"",MIN(Setup!C10,COUNT($C$4:$AG$4))) | AJ9: =IF(B9="","",AH9/COUNT($C$4:$AG$4)) | AK9: =IF(OR(B9="",N(AI9)=0),"",MIN(1,AH9/AI9))
B10: =IF(Setup!B11="","",Setup!B11) | AH10: =IF(B10="","",COUNTIF(C10:AG10,"✓")+COUNTIF(C10:AG10,"x")) | AI10: =IF(OR(B10="",Setup!C11=""),"",MIN(Setup!C11,COUNT($C$4:$AG$4))) | AJ10: =IF(B10="","",AH10/COUNT($C$4:$AG$4)) | AK10: =IF(OR(B10="",N(AI10)=0),"",MIN(1,AH10/AI10))
B11: =IF(Setup!B12="","",Setup!B12) | AH11: =IF(B11="","",COUNTIF(C11:AG11,"✓")+COUNTIF(C11:AG11,"x")) | AI11: =IF(OR(B11="",Setup!C12=""),"",MIN(Setup!C12,COUNT($C$4:$AG$4))) | AJ11: =IF(B11="","",AH11/COUNT($C$4:$AG$4)) | AK11: =IF(OR(B11="",N(AI11)=0),"",MIN(1,AH11/AI11))
B12: =IF(Setup!B13="","",Setup!B13) | AH12: =IF(B12="","",COUNTIF(C12:AG12,"✓")+COUNTIF(C12:AG12,"x")) | AI12: =IF(OR(B12="",Setup!C13=""),"",MIN(Setup!C13,COUNT($C$4:$AG$4))) | AJ12: =IF(B12="","",AH12/COUNT($C$4:$AG$4)) | AK12: =IF(OR(B12="",N(AI12)=0),"",MIN(1,AH12/AI12))
B13: =IF(Setup!B14="","",Setup!B14) | AH13: =IF(B13="","",COUNTIF(C13:AG13,"✓")+COUNTIF(C13:AG13,"x")) | AI13: =IF(OR(B13="",Setup!C14=""),"",MIN(Setup!C14,COUNT($C$4:$AG$4))) | AJ13: =IF(B13="","",AH13/COUNT($C$4:$AG$4)) | AK13: =IF(OR(B13="",N(AI13)=0),"",MIN(1,AH13/AI13))
B14: =IF(Setup!B15="","",Setup!B15) | AH14: =IF(B14="","",COUNTIF(C14:AG14,"✓")+COUNTIF(C14:AG14,"x")) | AI14: =IF(OR(B14="",Setup!C15=""),"",MIN(Setup!C15,COUNT($C$4:$AG$4))) | AJ14: =IF(B14="","",AH14/COUNT($C$4:$AG$4)) | AK14: =IF(OR(B14="",N(AI14)=0),"",MIN(1,AH14/AI14))
B15: =IF(Setup!B16="","",Setup!B16) | AH15: =IF(B15="","",COUNTIF(C15:AG15,"✓")+COUNTIF(C15:AG15,"x")) | AI15: =IF(OR(B15="",Setup!C16=""),"",MIN(Setup!C16,COUNT($C$4:$AG$4))) | AJ15: =IF(B15="","",AH15/COUNT($C$4:$AG$4)) | AK15: =IF(OR(B15="",N(AI15)=0),"",MIN(1,AH15/AI15))
B16: =IF(Setup!B17="","",Setup!B17) | AH16: =IF(B16="","",COUNTIF(C16:AG16,"✓")+COUNTIF(C16:AG16,"x")) | AI16: =IF(OR(B16="",Setup!C17=""),"",MIN(Setup!C17,COUNT($C$4:$AG$4))) | AJ16: =IF(B16="","",AH16/COUNT($C$4:$AG$4)) | AK16: =IF(OR(B16="",N(AI16)=0),"",MIN(1,AH16/AI16))
